Workbook
Name Approval: '[1]Lookup Tables'!$A$40:$A$41
Name CAV_Status_Options: '[1]Lookup Tables'!#REF!
Name CAV_Status_Options: '[1]Lookup Tables'!#REF!
Name Compliance_Level_Options: '[1]Lookup Tables'!$A$5:$A$10
Name Compliance_Level_Scores: '[1]Lookup Tables'!$A$5:$B$10
Name Implementation_Level_Options: '[1]Lookup Tables'!$A$23:$A$28
Name Implementation_Level_Scores: '[1]Lookup Tables'!$A$23:$B$28
Name Management_System_Level_Options: '[1]Lookup Tables'!$A$14:$A$19
Name Management_System_Level_Scores: '[1]Lookup Tables'!$A$14:$B$19
Name Status_Options: '[1]Lookup Tables'!$A$31:$A$33

Sheet SET
A1: 입사일기준 연차계산 및 사용관리를 위한 기본설정
A3: 1. 연차의 사용촉진 설정 | J3: 일부 | L3: 7
B4: * 신입연차 사용촉진 : 만1년미만 신입사원의 1개월 개근시마다 발생되는 연차는 사용촉진 대상이 아님.
B5: * 본 연차계산 및 관리대장은 만1년미만 연차의 사용기간을 취업규칙 또는 단체협약, 근로계약서에 다음년도 연차 사용기간 종료시 까지 하기로 명시한 경우에 해당됨.
B6: 없음 : 연차의 사용촉진을 하지 않고 매년 잔여연차를 수당으로 지급하거나, 이월시켜 사용하는 사업장의 경우 선택
B7: 전부 : 연차의 사용촉진을 하여 매년 잔여연차를 소멸시키는 사업장의 경우 선택
B8: 일부 : 전체 연차중 일부만 사용촉진하여 사용 또는 소멸시키고 그 나머지 연차는 수당으로 지급 또는 이월시키는 사업장의 경우 선택
B9: (일자) : 일부만 사용촉진하는 촉진연차수
A11: 2. 촉진없이 수당지급하다 연차의 사용촉진을 시작되는 경우 시작일 설정 | I11: 2014 | J11: 1 | L11: 1
B12: 미사용 연차를 수당으로 지급해왔으나, 연차가 증가됨에 따라 사용촉진으로 변경하는 경우 (해당없는경우 3년 이전으로 설정)
A14: 3. 연차 차감 항목 설정 (회사마다 적용 상황에 맞게 수정활용)
B15: 항목 | C15: 연차 | D15: 반차 | E15: 반반차 | F15: 경조 | G15: 훈련 | H15: 출산 | I15: 무급 | J15: 유급 | K15: 포상
B16: 차감수 | C16: 1 | D16: 0.5 | E16: 0.25 | F16: 0 | G16: 0 | H16: 0 | I16: 0 | J16: 0 | K16: 0
B17: (예시)
B18: @@차감항목 수정 설명보기 : | E18: https://blog.naver.com/bgheaven/221375853579
A20: 4. 근로기준법 변경 적용일 | J20: 42885
B21: (고용부의 개정연차 적용에 관련한 설명자료 있는 곳 입니다. ^^)
B22: http://www.moel.go.kr/policy/policydata/view.do?bbs_seq=20180600335
A24: [ 참고사항 ] 사용된 엑셀 함수의 설명
B25: =IF(논리값A,B,C) | F25: 논리값A 가 맞으면, B를 수행 또는 값으로 하고, 논리값A 가 아니라면 C를 수행 또는 값으로 한다.
B26: =ROUND(계산값,숫자) | F26: 숫자의 자리값으로 반올림한다. (소수점을 반올림할때 0, 10단위로 할때 1, 소수점2자리까지 할때 -2 …)
B27: =ROUNDUP(계산값,숫자) | F27: 숫자의 자리값으로 절상한다.
B28: =ROUNDDOWN(계산값,숫자) | F28: 숫자의 자리값으로 절하한다.
B29: =MIN(A,B) | F29: 계산값 또는 수 A, B 중 최소값을 구한다
B30: =DATEDIF(시작일,종료일,"M") | F30: 시작일과 종료일 사이의 개월수를 구한다
B31: =EDATE(시작일,경과개월수) | F31: 시작일로부터 경과개월수 이후 또는 이전의 날짜를 구한다
B32: =COUNTA(설정범위,참조값) | F32: 설정범위 내에서 참조값과 같은 셀의 수를 카운트 한다.
B33: =DATE(년,월,일) | F33: 년도값,지정월,지정일 의 날짜를 구한다.
B34: =YEAR(지정값) | F34: 지정값의 정수로된 연도를 구한다.
B35: =MONTH(지정값) | F35: 지정값의 정수로된 월을 구한다.
B36: =DAY(지정값) | F36: 지정값의 정수로된 일을 구한다.
B37: =TODAY() | F37: 현재의 날짜를 입력한다.

Sheet 입사일기준연차
R1: [근태목록 수정하기] | S1: https://blog.naver.com/bgheaven/221375853579
J2: 현재기준일자 | M2: =TODAY() -> 46157 | R2: [조건부서식 설명보기] | S2: https://blog.naver.com/bgheaven/221386977948
A4: 부서 | B4: 이 름 | C4: 입사일자 | D4: 최종근무 일자 | E4: 연차유급휴가 발생현황 (현재기준) | I4: 사용 누계 | J4: 사용 가능 연차 | K4: 연차유급휴가 정산 | N4: 사용권고통보일자 1차 촉진 / 2차 촉진 | P4: 연차유급휴가 사용 및 근태 기록부
E5: 사용시작일 (발생확정다음날) | F5: 연차 일수 | G5: 신입 연차 | H5: 전년도 이월 연차 | K5: 정산시점 (사용종료다음날) | L5: 정산 일수 | M5: 사용 촉진 | N5: 근로자 자율 사용계획서 제출 | O5: 사용자의 강제 사용일자 통보 | P5: 1 | Q5: 2 | R5: 3 | S5: 4 | T5: 5 | U5: 6 | V5: 7 | W5: 8 | X5: 9 | Y5: 10 | Z5: 11 | AA5: 12 | AB5: 13 | AC5: 14 | AD5: 15 | AE5: 16 | AF5: 17 | AG5: 18 | AH5: 19 | AI5: 20 | AJ5: 21 | AK5: 22 | AL5: 23 | AM5: 24 | AN5: 25 | AO5: 26 | AP5: 27 | AQ5: 28 | AR5: 29 | AS5: 30 | AT5: 31 | AU5: 32 | AV5: 33 | AW5: 34 | AX5: 35 | AY5: 36 | AZ5: 37 | BA5: 38 | BB5: 39 | BC5: 40 | BD5: 41 | BE5: 42 | BF5: 43 | BG5: 44 | BH5: 45 | BI5: 46 | BJ5: 47 | BK5: 48 | BL5: 49 | BM5: 50 | BN5: 51 | BO5: 52 | BP5: 53 | BQ5: 54 | BR5: 55 | BS5: 56 | BT5: 57 | BU5: 58 | BV5: 59 | BW5: 60
A6: 행정국장 | B6: 이승희 | C6: 42856 | E6: =IF(DATEDIF(C6,M$2,"m")<1,"",IF(C6=0,"",IF(EDATE(C6,12)<IF($D6>0,$D6-1,M$2),EDATE(C6,DATEDIF(C6,IF($D6>0,$D6-1,M$2+1),"y")*12),EDATE(C6,DATEDIF(C6,IF($D6>0,$D6-1,M$2+1),"m"))))) -> 46143 | F6: =IF(E6="",0,IF(EDATE(C6,12)<=E6,15+IF((YEAR(E6)-YEAR($C6))>20,10,INT((YEAR(E6)-YEAR($C6)-1)/2)),0)) -> 19 | G6: =IF(E6="",0,IF(E6>=EDATE(C6,12),IF(E6<EDATE(C6,24),IF(C6<SET!$J$20,0,MIN(DATEDIF(C6,E6,"m"),11)),0),IF(D6>C6,IF(E6<=EDATE(C6,12),MIN(DATEDIF(C6,D6+1,"m"),11),0),MIN(DATEDIF(C6,E6,"m"),11)))) -> 0 | H6: 4.5 | I6: =COUNTIF(P6:BW6,SET!$C$15)*SET!$C$16+COUNTIF(P6:BW6,SET!$D$15)*SET!$D$16+COUNTIF(P6:BW6,SET!E$15)*SET!$E$16+COUNTIF(P6:BW6,SET!$F$15)*SET!$F$16+COUNTIF(P6:BW6,SET!$G$15)*SET!$G$16+COUNTIF(P6:BW6,SET!$H$15)*SET!$H$16+COUNTIF(P6:BW6,SET!$I$15)*SET!$I$16+COUNTIF(P6:BW6,)*SET!$K$16+COUNTIF(P6:BW6,SET!$M$15)*SET!$M$16 -> 0.5 | J6: =F6+G6+H6-I6 -> 23 | K6: =IF(E6="","",IF(AND(D6>C6,EDATE(IF(EDATE(C6,12)<D6,C6,E6),12)>D6),"퇴직정산",IF((E6-C6)>=365,EDATE(E6,12),EDATE(C6,24)))) -> 46508 | L6: =IF(K6="퇴직정산",J6,IF((M$2-C6)<365,"미확정",IF(M6="유예","유예",J6-M6))) -> 16 | M6: =IF(C6=0,0,IF(K6="퇴직정산",0,IF(J6<=0,0,IF(EDATE(C6,3)>M$2,"유예",IF(SET!$J$3="없음",0,IF(SET!$J$3="전부",IF(E6>=DATE(YEAR(SET!$I$11),MONTH(SET!$J$11),DAY(SET!$L$11)),MAX(0,F6-IF(I6<(G6+H6),0,(I6-(G6+H6)))),0),IF(E6>=DATE(YEAR(SET!$I$11),MONTH(SET!$J$11),DAY(SET!$L$11)),MAX(0,MIN(F6,SET!$L$3)-IF(I6<(G6+H6),0,(I6-(G6+H6)))),0))))))) -> 7 | N6: =IF(D6=0,IF(M6>0,IF((E6-C6)>=365,EDATE(E6,6),EDATE(K6,-6)),""),"") -> 46327 | O6: =IF(D6=0,IF(M6>0,IF((E6-C6)>=365,EDATE(E6,10),EDATE(K6,-2)),""),"") -> 46447 | P6: 반차
P7: 26/04/28
A8: 간호부장 | B8: 최선경 | C8: 42856 | E8: =IF(DATEDIF(C8,M$2,"m")<1,"",IF(C8=0,"",IF(EDATE(C8,12)<IF($D8>0,$D8-1,M$2),EDATE(C8,DATEDIF(C8,IF($D8>0,$D8-1,M$2+1),"y")*12),EDATE(C8,DATEDIF(C8,IF($D8>0,$D8-1,M$2+1),"m"))))) -> 46143 | F8: =IF(E8="",0,IF(EDATE(C8,12)<=E8,15+IF((YEAR(E8)-YEAR($C8))>20,10,INT((YEAR(E8)-YEAR($C8)-1)/2)),0)) -> 19 | G8: =IF(E8="",0,IF(E8>=EDATE(C8,12),IF(E8<EDATE(C8,24),IF(C8<SET!$J$20,0,MIN(DATEDIF(C8,E8,"m"),11)),0),IF(D8>C8,IF(E8<=EDATE(C8,12),MIN(DATEDIF(C8,D8+1,"m"),11),0),MIN(DATEDIF(C8,E8,"m"),11)))) -> 0 | H8: 11.5 | I8: =COUNTIF(P8:BW8,SET!$C$15)*SET!$C$16+COUNTIF(P8:BW8,SET!$D$15)*SET!$D$16+COUNTIF(P8:BW8,SET!E$15)*SET!$E$16+COUNTIF(P8:BW8,SET!$F$15)*SET!$F$16+COUNTIF(P8:BW8,SET!$G$15)*SET!$G$16+COUNTIF(P8:BW8,SET!$H$15)*SET!$H$16+COUNTIF(P8:BW8,SET!$I$15)*SET!$I$16+COUNTIF(P8:BW8,)*SET!$K$16+COUNTIF(P8:BW8,SET!$M$15)*SET!$M$16 -> 1.5 | J8: =F8+G8+H8-I8 -> 29 | K8: =IF(E8="","",IF(AND(D8>C8,EDATE(IF(EDATE(C8,12)<D8,C8,E8),12)>D8),"퇴직정산",IF((E8-C8)>=365,EDATE(E8,12),EDATE(C8,24)))) -> 46508 | L8: =IF(K8="퇴직정산",J8,IF((M$2-C8)<365,"미확정",IF(M8="유예","유예",J8-M8))) -> 22 | M8: =IF(C8=0,0,IF(K8="퇴직정산",0,IF(J8<=0,0,IF(EDATE(C8,3)>M$2,"유예",IF(SET!$J$3="없음",0,IF(SET!$J$3="전부",IF(E8>=DATE(YEAR(SET!$I$11),MONTH(SET!$J$11),DAY(SET!$L$11)),MAX(0,F8-IF(I8<(G8+H8),0,(I8-(G8+H8)))),0),IF(E8>=DATE(YEAR(SET!$I$11),MONTH(SET!$J$11),DAY(SET!$L$11)),MAX(0,MIN(F8,SET!$L$3)-IF(I8<(G8+H8),0,(I8-(G8+H8)))),0))))))) -> 7 | N8: =IF(D8=0,IF(M8>0,IF((E8-C8)>=365,EDATE(E8,6),EDATE(K8,-6)),""),"") -> 46327 | O8: =IF(D8=0,IF(M8>0,IF((E8-C8)>=365,EDATE(E8,10),EDATE(K8,-2)),""),"") -> 46447 | P8: 반차 | Q8: 반차 | R8: 반차
P9: 26/04/16 | Q9: 26/04/17 | R9: 26/04/27
A10: 감염관리 팀장 | B10: 박미란 | C10: 43906 | E10: =IF(DATEDIF(C10,M$2,"m")<1,"",IF(C10=0,"",IF(EDATE(C10,12)<IF($D10>0,$D10-1,M$2),EDATE(C10,DATEDIF(C10,IF($D10>0,$D10-1,M$2+1),"y")*12),EDATE(C10,DATEDIF(C10,IF($D10>0,$D10-1,M$2+1),"m"))))) -> 46097 | F10: =IF(E10="",0,IF(EDATE(C10,12)<=E10,15+IF((YEAR(E10)-YEAR($C10))>20,10,INT((YEAR(E10)-YEAR($C10)-1)/2)),0)) -> 17 | G10: =IF(E10="",0,IF(E10>=EDATE(C10,12),IF(E10<EDATE(C10,24),IF(C10<SET!$J$20,0,MIN(DATEDIF(C10,E10,"m"),11)),0),IF(D10>C10,IF(E10<=EDATE(C10,12),MIN(DATEDIF(C10,D10+1,"m"),11),0),MIN(DATEDIF(C10,E10,"m"),11)))) -> 0 | H10: 12.5 | I10: =COUNTIF(P10:BW10,SET!$C$15)*SET!$C$16+COUNTIF(P10:BW10,SET!$D$15)*SET!$D$16+COUNTIF(P10:BW10,SET!E$15)*SET!$E$16+COUNTIF(P10:BW10,SET!$F$15)*SET!$F$16+COUNTIF(P10:BW10,SET!$G$15)*SET!$G$16+COUNTIF(P10:BW10,SET!$H$15)*SET!$H$16+COUNTIF(P10:BW10,SET!$I$15)*SET!$I$16+COUNTIF(P10:BW10,)*SET!$K$16+COUNTIF(P10:BW10,SET!$M$15)*SET!$M$16 -> 4 | J10: =F10+G10+H10-I10 -> 25.5 | K10: =IF(E10="","",IF(AND(D10>C10,EDATE(IF(EDATE(C10,12)<D10,C10,E10),12)>D10),"퇴직정산",IF((E10-C10)>=365,EDATE(E10,12),EDATE(C10,24)))) -> 46462 | L10: =IF(K10="퇴직정산",J10,IF((M$2-C10)<365,"미확정",IF(M10="유예","유예",J10-M10))) -> 18.5 | M10: =IF(C10=0,0,IF(K10="퇴직정산",0,IF(J10<=0,0,IF(EDATE(C10,3)>M$2,"유예",IF(SET!$J$3="없음",0,IF(SET!$J$3="전부",IF(E10>=DATE(YEAR(SET!$I$11),MONTH(SET!$J$11),DAY(SET!$L$11)),MAX(0,F10-IF(I10<(G10+H10),0,(I10-(G10+H10)))),0),IF(E10>=DATE(YEAR(SET!$I$11),MONTH(SET!$J$11),DAY(SET!$L$11)),MAX(0,MIN(F10,SET!$L$3)-IF(I10<(G10+H10),0,(I10-(G10+H10)))),0))))))) -> 7 | N10: =IF(D10=0,IF(M10>0,IF((E10-C10)>=365,EDATE(E10,6),EDATE(K10,-6)),""),"") -> 46281 | O10: =IF(D10=0,IF(M10>0,IF((E10-C10)>=365,EDATE(E10,10),EDATE(K10,-2)),""),"") -> 46403 | P10: 연차 | Q10: 연차 | R10: 연차 | S10: 연차
P11: 26/03/30 | Q11: 26/03/31 | R11: 26/04/01 | S11: 26/04/02
A12: 환자안전 관리팀장 | B12: 이윤임 | C12: 43108 | E12: =IF(DATEDIF(C12,M$2,"m")<1,"",IF(C12=0,"",IF(EDATE(C12,12)<IF($D12>0,$D12-1,M$2),EDATE(C12,DATEDIF(C12,IF($D12>0,$D12-1,M$2+1),"y")*12),EDATE(C12,DATEDIF(C12,IF($D12>0,$D12-1,M$2+1),"m"))))) -> 46030 | F12: =IF(E12="",0,IF(EDATE(C12,12)<=E12,15+IF((YEAR(E12)-YEAR($C12))>20,10,INT((YEAR(E12)-YEAR($C12)-1)/2)),0)) -> 18 | G12: =IF(E12="",0,IF(E12>=EDATE(C12,12),IF(E12<EDATE(C12,24),IF(C12<SET!$J$20,0,MIN(DATEDIF(C12,E12,"m"),11)),0),IF(D12>C12,IF(E12<=EDATE(C12,12),MIN(DATEDIF(C12,D12+1,"m"),11),0),MIN(DATEDIF(C12,E12,"m"),11)))) -> 0 | H12: 1 | I12: =COUNTIF(P12:BW12,SET!$C$15)*SET!$C$16+COUNTIF(P12:BW12,SET!$D$15)*SET!$D$16+COUNTIF(P12:BW12,SET!E$15)*SET!$E$16+COUNTIF(P12:BW12,SET!$F$15)*SET!$F$16+COUNTIF(P12:BW12,SET!$G$15)*SET!$G$16+COUNTIF(P12:BW12,SET!$H$15)*SET!$H$16+COUNTIF(P12:BW12,SET!$I$15)*SET!$I$16+COUNTIF(P12:BW12,)*SET!$K$16+COUNTIF(P12:BW12,SET!$M$15)*SET!$M$16 -> 9.5 | J12: =F12+G12+H12-I12 -> 9.5 | K12: =IF(E12="","",IF(AND(D12>C12,EDATE(IF(EDATE(C12,12)<D12,C12,E12),12)>D12),"퇴직정산",IF((E12-C12)>=365,EDATE(E12,12),EDATE(C12,24)))) -> 46395 | L12: =IF(K12="퇴직정산",J12,IF((M$2-C12)<365,"미확정",IF(M12="유예","유예",J12-M12))) -> 9.5 | M12: =IF(C12=0,0,IF(K12="퇴직정산",0,IF(J12<=0,0,IF(EDATE(C12,3)>M$2,"유예",IF(SET!$J$3="없음",0,IF(SET!$J$3="전부",IF(E12>=DATE(YEAR(SET!$I$11),MONTH(SET!$J$11),DAY(SET!$L$11)),MAX(0,F12-IF(I12<(G12+H12),0,(I12-(G12+H12)))),0),IF(E12>=DATE(YEAR(SET!$I$11),MONTH(SET!$J$11),DAY(SET!$L$11)),MAX(0,MIN(F12,SET!$L$3)-IF(I12<(G12+H12),0,(I12-(G12+H12)))),0))))))) -> 0 | N12: =IF(D12=0,IF(M12>0,IF((E12-C12)>=365,EDATE(E12,6),EDATE(K12,-6)),""),"") | O12: =IF(D12=0,IF(M12>0,IF((E12-C12)>=365,EDATE(E12,10),EDATE(K12,-2)),""),"") | P12: 반차 | Q12: 반차 | R12: 연차 | S12: 반차 | T12: 연차 | U12: 반차 | V12: 반차 | W12: 반차 | X12: 연차 | Y12: 연차 | Z12: 연차 | AA12: 연차 | AB12: 반차
P13: 25/12/22 | Q13: 25/12/31 | R13: 26/01/02 | S13: 26/01/08 | T13: 26/01/19 | U13: 26/02/02 | V13: 26/02/06 | W13: 26/02/26 | X13: 26/02/27 | Y13: 26/03/11 | Z13: 26/03/12 | AA13: 26/03/13 | AB13: 26/03/20
A14: 간호행정 | B14: RN 윤수경 | C14: 45008 | E14: =IF(DATEDIF(C14,M$2,"m")<1,"",IF(C14=0,"",IF(EDATE(C14,12)<IF($D14>0,$D14-1,M$2),EDATE(C14,DATEDIF(C14,IF($D14>0,$D14-1,M$2+1),"y")*12),EDATE(C14,DATEDIF(C14,IF($D14>0,$D14-1,M$2+1),"m"))))) -> 46104 | F14: =IF(E14="",0,IF(EDATE(C14,12)<=E14,15+IF((YEAR(E14)-YEAR($C14))>20,10,INT((YEAR(E14)-YEAR($C14)-1)/2)),0)) -> 16 | G14: =IF(E14="",0,IF(E14>=EDATE(C14,12),IF(E14<EDATE(C14,24),IF(C14<SET!$J$20,0,MIN(DATEDIF(C14,E14,"m"),11)),0),IF(D14>C14,IF(E14<=EDATE(C14,12),MIN(DATEDIF(C14,D14+1,"m"),11),0),MIN(DATEDIF(C14,E14,"m"),11)))) -> 0 | H14: 0.5 | I14: =COUNTIF(P14:BW14,SET!$C$15)*SET!$C$16+COUNTIF(P14:BW14,SET!$D$15)*SET!$D$16+COUNTIF(P14:BW14,SET!E$15)*SET!$E$16+COUNTIF(P14:BW14,SET!$F$15)*SET!$F$16+COUNTIF(P14:BW14,SET!$G$15)*SET!$G$16+COUNTIF(P14:BW14,SET!$H$15)*SET!$H$16+COUNTIF(P14:BW14,SET!$I$15)*SET!$I$16+COUNTIF(P14:BW14,)*SET!$K$16+COUNTIF(P14:BW14,SET!$M$15)*SET!$M$16 -> 0 | J14: =F14+G14+H14-I14 -> 16.5 | K14: =IF(E14="","",IF(AND(D14>C14,EDATE(IF(EDATE(C14,12)<D14,C14,E14),12)>D14),"퇴직정산",IF((E14-C14)>=365,EDATE(E14,12),EDATE(C14,24)))) -> 46469 | L14: =IF(K14="퇴직정산",J14,IF((M$2-C14)<365,"미확정",IF(M14="유예","유예",J14-M14))) -> 9.5 | M14: =IF(C14=0,0,IF(K14="퇴직정산",0,IF(J14<=0,0,IF(EDATE(C14,3)>M$2,"유예",IF(SET!$J$3="없음",0,IF(SET!$J$3="전부",IF(E14>=DATE(YEAR(SET!$I$11),MONTH(SET!$J$11),DAY(SET!$L$11)),MAX(0,F14-IF(I14<(G14+H14),0,(I14-(G14+H14)))),0),IF(E14>=DATE(YEAR(SET!$I$11),MONTH(SET!$J$11),DAY(SET!$L$11)),MAX(0,MIN(F14,SET!$L$3)-IF(I14<(G14+H14),0,(I14-(G14+H14)))),0))))))) -> 7 | N14: =IF(D14=0,IF(M14>0,IF((E14-C14)>=365,EDATE(E14,6),EDATE(K14,-6)),""),"") -> 46288 | O14: =IF(D14=0,IF(M14>0,IF((E14-C14)>=365,EDATE(E14,10),EDATE(K14,-2)),""),"") -> 46410
B16: RN 임수빈 | C16: 45299 | E16: =IF(DATEDIF(C16,M$2,"m")<1,"",IF(C16=0,"",IF(EDATE(C16,12)<IF($D16>0,$D16-1,M$2),EDATE(C16,DATEDIF(C16,IF($D16>0,$D16-1,M$2+1),"y")*12),EDATE(C16,DATEDIF(C16,IF($D16>0,$D16-1,M$2+1),"m"))))) -> 46030 | F16: =IF(E16="",0,IF(EDATE(C16,12)<=E16,15+IF((YEAR(E16)-YEAR($C16))>20,10,INT((YEAR(E16)-YEAR($C16)-1)/2)),0)) -> 15 | G16: =IF(E16="",0,IF(E16>=EDATE(C16,12),IF(E16<EDATE(C16,24),IF(C16<SET!$J$20,0,MIN(DATEDIF(C16,E16,"m"),11)),0),IF(D16>C16,IF(E16<=EDATE(C16,12),MIN(DATEDIF(C16,D16+1,"m"),11),0),MIN(DATEDIF(C16,E16,"m"),11)))) -> 0 | H16: 6.5 | I16: =COUNTIF(P16:BW16,SET!$C$15)*SET!$C$16+COUNTIF(P16:BW16,SET!$D$15)*SET!$D$16+COUNTIF(P16:BW16,SET!E$15)*SET!$E$16+COUNTIF(P16:BW16,SET!$F$15)*SET!$F$16+COUNTIF(P16:BW16,SET!$G$15)*SET!$G$16+COUNTIF(P16:BW16,SET!$H$15)*SET!$H$16+COUNTIF(P16:BW16,SET!$I$15)*SET!$I$16+COUNTIF(P16:BW16,)*SET!$K$16+COUNTIF(P16:BW16,SET!$M$15)*SET!$M$16 -> 3.5 | J16: =F16+G16+H16-I16 -> 18 | K16: =IF(E16="","",IF(AND(D16>C16,EDATE(IF(EDATE(C16,12)<D16,C16,E16),12)>D16),"퇴직정산",IF((E16-C16)>=365,EDATE(E16,12),EDATE(C16,24)))) -> 46395 | L16: =IF(K16="퇴직정산",J16,IF((M$2-C16)<365,"미확정",IF(M16="유예","유예",J16-M16))) -> 11 | M16: =IF(C16=0,0,IF(K16="퇴직정산",0,IF(J16<=0,0,IF(EDATE(C16,3)>M$2,"유예",IF(SET!$J$3="없음",0,IF(SET!$J$3="전부",IF(E16>=DATE(YEAR(SET!$I$11),MONTH(SET!$J$11),DAY(SET!$L$11)),MAX(0,F16-IF(I16<(G16+H16),0,(I16-(G16+H16)))),0),IF(E16>=DATE(YEAR(SET!$I$11),MONTH(SET!$J$11),DAY(SET!$L$11)),MAX(0,MIN(F16,SET!$L$3)-IF(I16<(G16+H16),0,(I16-(G16+H16)))),0))))))) -> 7 | N16: =IF(D16=0,IF(M16>0,IF((E16-C16)>=365,EDATE(E16,6),EDATE(K16,-6)),""),"") -> 46211 | O16: =IF(D16=0,IF(M16>0,IF((E16-C16)>=365,EDATE(E16,10),EDATE(K16,-2)),""),"") -> 46334 | P16: 연차 | Q16: 연차 | R16: 연차 | S16: 반차
P17: 25/12/09 | Q17: 26/02/05 | R17: 26/02/11 | S17: 26/02/27
B18: RN 한선화 | C18: 45691 | E18: =IF(DATEDIF(C18,M$2,"m")<1,"",IF(C18=0,"",IF(EDATE(C18,12)<IF($D18>0,$D18-1,M$2),EDATE(C18,DATEDIF(C18,IF($D18>0,$D18-1,M$2+1),"y")*12),EDATE(C18,DATEDIF(C18,IF($D18>0,$D18-1,M$2+1),"m"))))) -> 46056 | F18: =IF(E18="",0,IF(EDATE(C18,12)<=E18,15+IF((YEAR(E18)-YEAR($C18))>20,10,INT((YEAR(E18)-YEAR($C18)-1)/2)),0)) -> 15 | G18: =IF(E18="",0,IF(E18>=EDATE(C18,12),IF(E18<EDATE(C18,24),IF(C18<SET!$J$20,0,MIN(DATEDIF(C18,E18,"m"),11)),0),IF(D18>C18,IF(E18<=EDATE(C18,12),MIN(DATEDIF(C18,D18+1,"m"),11),0),MIN(DATEDIF(C18,E18,"m"),11)))) -> 11 | I18: =COUNTIF(P18:BW18,SET!$C$15)*SET!$C$16+COUNTIF(P18:BW18,SET!$D$15)*SET!$D$16+COUNTIF(P18:BW18,SET!E$15)*SET!$E$16+COUNTIF(P18:BW18,SET!$F$15)*SET!$F$16+COUNTIF(P18:BW18,SET!$G$15)*SET!$G$16+COUNTIF(P18:BW18,SET!$H$15)*SET!$H$16+COUNTIF(P18:BW18,SET!$I$15)*SET!$I$16+COUNTIF(P18:BW18,)*SET!$K$16+COUNTIF(P18:BW18,SET!$M$15)*SET!$M$16 -> 9.5 | J18: =F18+G18+H18-I18 -> 16.5 | K18: =IF(E18="","",IF(AND(D18>C18,EDATE(IF(EDATE(C18,12)<D18,C18,E18),12)>D18),"퇴직정산",IF((E18-C18)>=365,EDATE(E18,12),EDATE(C18,24)))) -> 46421 | L18: =IF(K18="퇴직정산",J18,IF((M$2-C18)<365,"미확정",IF(M18="유예","유예",J18-M18))) -> 9.5 | M18: =IF(C18=0,0,IF(K18="퇴직정산",0,IF(J18<=0,0,IF(EDATE(C18,3)>M$2,"유예",IF(SET!$J$3="없음",0,IF(SET!$J$3="전부",IF(E18>=DATE(YEAR(SET!$I$11),MONTH(SET!$J$11),DAY(SET!$L$11)),MAX(0,F18-IF(I18<(G18+H18),0,(I18-(G18+H18)))),0),IF(E18>=DATE(YEAR(SET!$I$11),MONTH(SET!$J$11),DAY(SET!$L$11)),MAX(0,MIN(F18,SET!$L$3)-IF(I18<(G18+H18),0,(I18-(G18+H18)))),0))))))) -> 7 | N18: =IF(D18=0,IF(M18>0,IF((E18-C18)>=365,EDATE(E18,6),EDATE(K18,-6)),""),"") -> 46237 | O18: =IF(D18=0,IF(M18>0,IF((E18-C18)>=365,EDATE(E18,10),EDATE(K18,-2)),""),"") -> 46359 | P18: 연차 | Q18: 반차 | R18: 연차 | S18: 연차 | T18: 반차 | U18: 연차 | V18: 반차 | W18: 반차 | X18: 연차 | Y18: 반차 | Z18: 연차 | AA18: 연차
P19: 45761 | Q19: 45840 | R19: 45867 | S19: 45868 | T19: 45912 | U19: 45929 | V19: 25/12/29 | W19: 25/12/03 | X19: 26/01/02 | Y19: 26/01/07 | Z19: 26/01/15 | AA19: 26/01/16
A20: 3병동 | B20: HR 이고경 | C20: 43493 | E20: =IF(DATEDIF(C20,M$2,"m")<1,"",IF(C20=0,"",IF(EDATE(C20,12)<IF($D20>0,$D20-1,M$2),EDATE(C20,DATEDIF(C20,IF($D20>0,$D20-1,M$2+1),"y")*12),EDATE(C20,DATEDIF(C20,IF($D20>0,$D20-1,M$2+1),"m"))))) -> 46050 | F20: =IF(E20="",0,IF(EDATE(C20,12)<=E20,15+IF((YEAR(E20)-YEAR($C20))>20,10,INT((YEAR(E20)-YEAR($C20)-1)/2)),0)) -> 18 | G20: =IF(E20="",0,IF(E20>=EDATE(C20,12),IF(E20<EDATE(C20,24),IF(C20<SET!$J$20,0,MIN(DATEDIF(C20,E20,"m"),11)),0),IF(D20>C20,IF(E20<=EDATE(C20,12),MIN(DATEDIF(C20,D20+1,"m"),11),0),MIN(DATEDIF(C20,E20,"m"),11)))) -> 0 | H20: 14.5 | I20: =COUNTIF(P20:BW20,SET!$C$15)*SET!$C$16+COUNTIF(P20:BW20,SET!$D$15)*SET!$D$16+COUNTIF(P20:BW20,SET!E$15)*SET!$E$16+COUNTIF(P20:BW20,SET!$F$15)*SET!$F$16+COUNTIF(P20:BW20,SET!$G$15)*SET!$G$16+COUNTIF(P20:BW20,SET!$H$15)*SET!$H$16+COUNTIF(P20:BW20,SET!$I$15)*SET!$I$16+COUNTIF(P20:BW20,)*SET!$K$16+COUNTIF(P20:BW20,SET!$M$15)*SET!$M$16 -> 8.5 | J20: =F20+G20+H20-I20 -> 24 | K20: =IF(E20="","",IF(AND(D20>C20,EDATE(IF(EDATE(C20,12)<D20,C20,E20),12)>D20),"퇴직정산",IF((E20-C20)>=365,EDATE(E20,12),EDATE(C20,24)))) -> 46415 | L20: =IF(K20="퇴직정산",J20,IF((M$2-C20)<365,"미확정",IF(M20="유예","유예",J20-M20))) -> 17 | M20: =IF(C20=0,0,IF(K20="퇴직정산",0,IF(J20<=0,0,IF(EDATE(C20,3)>M$2,"유예",IF(SET!$J$3="없음",0,IF(SET!$J$3="전부",IF(E20>=DATE(YEAR(SET!$I$11),MONTH(SET!$J$11),DAY(SET!$L$11)),MAX(0,F20-IF(I20<(G20+H20),0,(I20-(G20+H20)))),0),IF(E20>=DATE(YEAR(SET!$I$11),MONTH(SET!$J$11),DAY(SET!$L$11)),MAX(0,MIN(F20,SET!$L$3)-IF(I20<(G20+H20),0,(I20-(G20+H20)))),0))))))) -> 7 | N20: =IF(D20=0,IF(M20>0,IF((E20-C20)>=365,EDATE(E20,6),EDATE(K20,-6)),""),"") -> 46231 | O20: =IF(D20=0,IF(M20>0,IF((E20-C20)>=365,EDATE(E20,10),EDATE(K20,-2)),""),"") -> 46354 | P20: 연차 | Q20: 연차 | R20: 반차 | S20: 연차 | T20: 반차 | U20: 연차 | V20: 연차 | W20: 연차 | X20: 연차 | Y20: 반차
P21: 26/01/24 | Q21: 26/01/25 | R21: 26/02/07 | S21: 26/02/19 | T21: 26/03/14 | U21: 26/04/09 | V21: 26/04/10 | W21: 26/04/11 | X21: 26/04/12 | Y21: 26/04/25
B22: CN 배효정 | C22: 43864 | E22: =IF(DATEDIF(C22,M$2,"m")<1,"",IF(C22=0,"",IF(EDATE(C22,12)<IF($D22>0,$D22-1,M$2),EDATE(C22,DATEDIF(C22,IF($D22>0,$D22-1,M$2+1),"y")*12),EDATE(C22,DATEDIF(C22,IF($D22>0,$D22-1,M$2+1),"m"))))) -> 46056 | F22: =IF(E22="",0,IF(EDATE(C22,12)<=E22,15+IF((YEAR(E22)-YEAR($C22))>20,10,INT((YEAR(E22)-YEAR($C22)-1)/2)),0)) -> 17 | G22: =IF(E22="",0,IF(E22>=EDATE(C22,12),IF(E22<EDATE(C22,24),IF(C22<SET!$J$20,0,MIN(DATEDIF(C22,E22,"m"),11)),0),IF(D22>C22,IF(E22<=EDATE(C22,12),MIN(DATEDIF(C22,D22+1,"m"),11),0),MIN(DATEDIF(C22,E22,"m"),11)))) -> 0 | H22: 29 | I22: =COUNTIF(P22:BW22,SET!$C$15)*SET!$C$16+COUNTIF(P22:BW22,SET!$D$15)*SET!$D$16+COUNTIF(P22:BW22,SET!E$15)*SET!$E$16+COUNTIF(P22:BW22,SET!$F$15)*SET!$F$16+COUNTIF(P22:BW22,SET!$G$15)*SET!$G$16+COUNTIF(P22:BW22,SET!$H$15)*SET!$H$16+COUNTIF(P22:BW22,SET!$I$15)*SET!$I$16+COUNTIF(P22:BW22,)*SET!$K$16+COUNTIF(P22:BW22,SET!$M$15)*SET!$M$16 -> 0 | J22: =F22+G22+H22-I22 -> 46 | K22: =IF(E22="","",IF(AND(D22>C22,EDATE(IF(EDATE(C22,12)<D22,C22,E22),12)>D22),"퇴직정산",IF((E22-C22)>=365,EDATE(E22,12),EDATE(C22,24)))) -> 46421 | L22: =IF(K22="퇴직정산",J22,IF((M$2-C22)<365,"미확정",IF(M22="유예","유예",J22-M22))) -> 39 | M22: =IF(C22=0,0,IF(K22="퇴직정산",0,IF(J22<=0,0,IF(EDATE(C22,3)>M$2,"유예",IF(SET!$J$3="없음",0,IF(SET!$J$3="전부",IF(E22>=DATE(YEAR(SET!$I$11),MONTH(SET!$J$11),DAY(SET!$L$11)),MAX(0,F22-IF(I22<(G22+H22),0,(I22-(G22+H22)))),0),IF(E22>=DATE(YEAR(SET!$I$11),MONTH(SET!$J$11),DAY(SET!$L$11)),MAX(0,MIN(F22,SET!$L$3)-IF(I22<(G22+H22),0,(I22-(G22+H22)))),0))))))) -> 7 | N22: =IF(D22=0,IF(M22>0,IF((E22-C22)>=365,EDATE(E22,6),EDATE(K22,-6)),""),"") -> 46237 | O22: =IF(D22=0,IF(M22>0,IF((E22-C22)>=365,EDATE(E22,10),EDATE(K22,-2)),""),"") -> 46359
B24: RN 사공금옥 | C24: 43467 | E24: =IF(DATEDIF(C24,M$2,"m")<1,"",IF(C24=0,"",IF(EDATE(C24,12)<IF($D24>0,$D24-1,M$2),EDATE(C24,DATEDIF(C24,IF($D24>0,$D24-1,M$2+1),"y")*12),EDATE(C24,DATEDIF(C24,IF($D24>0,$D24-1,M$2+1),"m"))))) -> 46024 | F24: =IF(E24="",0,IF(EDATE(C24,12)<=E24,15+IF((YEAR(E24)-YEAR($C24))>20,10,INT((YEAR(E24)-YEAR($C24)-1)/2)),0)) -> 18 | G24: =IF(E24="",0,IF(E24>=EDATE(C24,12),IF(E24<EDATE(C24,24),IF(C24<SET!$J$20,0,MIN(DATEDIF(C24,E24,"m"),11)),0),IF(D24>C24,IF(E24<=EDATE(C24,12),MIN(DATEDIF(C24,D24+1,"m"),11),0),MIN(DATEDIF(C24,E24,"m"),11)))) -> 0 | H24: 5.5 | I24: =COUNTIF(P24:BW24,SET!$C$15)*SET!$C$16+COUNTIF(P24:BW24,SET!$D$15)*SET!$D$16+COUNTIF(P24:BW24,SET!E$15)*SET!$E$16+COUNTIF(P24:BW24,SET!$F$15)*SET!$F$16+COUNTIF(P24:BW24,SET!$G$15)*SET!$G$16+COUNTIF(P24:BW24,SET!$H$15)*SET!$H$16+COUNTIF(P24:BW24,SET!$I$15)*SET!$I$16+COUNTIF(P24:BW24,)*SET!$K$16+COUNTIF(P24:BW24,SET!$M$15)*SET!$M$16 -> 7 | J24: =F24+G24+H24-I24 -> 16.5 | K24: =IF(E24="","",IF(AND(D24>C24,EDATE(IF(EDATE(C24,12)<D24,C24,E24),12)>D24),"퇴직정산",IF((E24-C24)>=365,EDATE(E24,12),EDATE(C24,24)))) -> 46389 | L24: =IF(K24="퇴직정산",J24,IF((M$2-C24)<365,"미확정",IF(M24="유예","유예",J24-M24))) -> 11 | M24: =IF(C24=0,0,IF(K24="퇴직정산",0,IF(J24<=0,0,IF(EDATE(C24,3)>M$2,"유예",IF(SET!$J$3="없음",0,IF(SET!$J$3="전부",IF(E24>=DATE(YEAR(SET!$I$11),MONTH(SET!$J$11),DAY(SET!$L$11)),MAX(0,F24-IF(I24<(G24+H24),0,(I24-(G24+H24)))),0),IF(E24>=DATE(YEAR(SET!$I$11),MONTH(SET!$J$11),DAY(SET!$L$11)),MAX(0,MIN(F24,SET!$L$3)-IF(I24<(G24+H24),0,(I24-(G24+H24)))),0))))))) -> 5.5 | N24: =IF(D24=0,IF(M24>0,IF((E24-C24)>=365,EDATE(E24,6),EDATE(K24,-6)),""),"") -> 46205 | O24: =IF(D24=0,IF(M24>0,IF((E24-C24)>=365,EDATE(E24,10),EDATE(K24,-2)),""),"") -> 46328 | P24: 연차 | Q24: 반차 | R24: 연차 | S24: 연차 | T24: 연차 | U24: 연차 | V24: 반차 | W24: 연차
P25: 25/12/26 | Q25: 25/12/16 | R25: 26/01/03 | S25: 26/01/04 | T25: 26/02/12 | U25: 26/02/13 | V25: 26/04/02 | W25: 26/04/03
B26: RN 김채원 | C26: 42835 | E26: =IF(DATEDIF(C26,M$2,"m")<1,"",IF(C26=0,"",IF(EDATE(C26,12)<IF($D26>0,$D26-1,M$2),EDATE(C26,DATEDIF(C26,IF($D26>0,$D26-1,M$2+1),"y")*12),EDATE(C26,DATEDIF(C26,IF($D26>0,$D26-1,M$2+1),"m"))))) -> 46122 | F26: =IF(E26="",0,IF(EDATE(C26,12)<=E26,15+IF((YEAR(E26)-YEAR($C26))>20,10,INT((YEAR(E26)-YEAR($C26)-1)/2)),0)) -> 19 | G26: =IF(E26="",0,IF(E26>=EDATE(C26,12),IF(E26<EDATE(C26,24),IF(C26<SET!$J$20,0,MIN(DATEDIF(C26,E26,"m"),11)),0),IF(D26>C26,IF(E26<=EDATE(C26,12),MIN(DATEDIF(C26,D26+1,"m"),11),0),MIN(DATEDIF(C26,E26,"m"),11)))) -> 0 | H26: 12 | I26: =COUNTIF(P26:BW26,SET!$C$15)*SET!$C$16+COUNTIF(P26:BW26,SET!$D$15)*SET!$D$16+COUNTIF(P26:BW26,SET!E$15)*SET!$E$16+COUNTIF(P26:BW26,SET!$F$15)*SET!$F$16+COUNTIF(P26:BW26,SET!$G$15)*SET!$G$16+COUNTIF(P26:BW26,SET!$H$15)*SET!$H$16+COUNTIF(P26:BW26,SET!$I$15)*SET!$I$16+COUNTIF(P26:BW26,)*SET!$K$16+COUNTIF(P26:BW26,SET!$M$15)*SET!$M$16 -> 4 | J26: =F26+G26+H26-I26 -> 27 | K26: =IF(E26="","",IF(AND(D26>C26,EDATE(IF(EDATE(C26,12)<D26,C26,E26),12)>D26),"퇴직정산",IF((E26-C26)>=365,EDATE(E26,12),EDATE(C26,24)))) -> 46487 | L26: =IF(K26="퇴직정산",J26,IF((M$2-C26)<365,"미확정",IF(M26="유예","유예",J26-M26))) -> 20 | M26: =IF(C26=0,0,IF(K26="퇴직정산",0,IF(J26<=0,0,IF(EDATE(C26,3)>M$2,"유예",IF(SET!$J$3="없음",0,IF(SET!$J$3="전부",IF(E26>=DATE(YEAR(SET!$I$11),MONTH(SET!$J$11),DAY(SET!$L$11)),MAX(0,F26-IF(I26<(G26+H26),0,(I26-(G26+H26)))),0),IF(E26>=DATE(YEAR(SET!$I$11),MONTH(SET!$J$11),DAY(SET!$L$11)),MAX(0,MIN(F26,SET!$L$3)-IF(I26<(G26+H26),0,(I26-(G26+H26)))),0))))))) -> 7 | N26: =IF(D26=0,IF(M26>0,IF((E26-C26)>=365,EDATE(E26,6),EDATE(K26,-6)),""),"") -> 46305 | O26: =IF(D26=0,IF(M26>0,IF((E26-C26)>=365,EDATE(E26,10),EDATE(K26,-2)),""),"") -> 46428 | P26: 연차 | Q26: 연차 | R26: 연차 | S26: 연차
P27: 26/03/14 | Q27: 26/04/03 | R27: 26/04/05 | S27: 26/04/06
B28: RN 유지수 | C28: 44046 | E28: =IF(DATEDIF(C28,M$2,"m")<1,"",IF(C28=0,"",IF(EDATE(C28,12)<IF($D28>0,$D28-1,M$2),EDATE(C28,DATEDIF(C28,IF($D28>0,$D28-1,M$2+1),"y")*12),EDATE(C28,DATEDIF(C28,IF($D28>0,$D28-1,M$2+1),"m"))))) -> 45872 | F28: =IF(E28="",0,IF(EDATE(C28,12)<=E28,15+IF((YEAR(E28)-YEAR($C28))>20,10,INT((YEAR(E28)-YEAR($C28)-1)/2)),0)) -> 17 | G28: =IF(E28="",0,IF(E28>=EDATE(C28,12),IF(E28<EDATE(C28,24),IF(C28<SET!$J$20,0,MIN(DATEDIF(C28,E28,"m"),11)),0),IF(D28>C28,IF(E28<=EDATE(C28,12),MIN(DATEDIF(C28,D28+1,"m"),11),0),MIN(DATEDIF(C28,E28,"m"),11)))) -> 0 | H28: 1 | I28: =COUNTIF(P28:BW28,SET!$C$15)*SET!$C$16+COUNTIF(P28:BW28,SET!$D$15)*SET!$D$16+COUNTIF(P28:BW28,SET!E$15)*SET!$E$16+COUNTIF(P28:BW28,SET!$F$15)*SET!$F$16+COUNTIF(P28:BW28,SET!$G$15)*SET!$G$16+COUNTIF(P28:BW28,SET!$H$15)*SET!$H$16+COUNTIF(P28:BW28,SET!$I$15)*SET!$I$16+COUNTIF(P28:BW28,)*SET!$K$16+COUNTIF(P28:BW28,SET!$M$15)*SET!$M$16 -> 13 | J28: =F28+G28+H28-I28 -> 5 | K28: =IF(E28="","",IF(AND(D28>C28,EDATE(IF(EDATE(C28,12)<D28,C28,E28),12)>D28),"퇴직정산",IF((E28-C28)>=365,EDATE(E28,12),EDATE(C28,24)))) -> 46237 | L28: =IF(K28="퇴직정산",J28,IF((M$2-C28)<365,"미확정",IF(M28="유예","유예",J28-M28))) -> 5 | M28: =IF(C28=0,0,IF(K28="퇴직정산",0,IF(J28<=0,0,IF(EDATE(C28,3)>M$2,"유예",IF(SET!$J$3="없음",0,IF(SET!$J$3="전부",IF(E28>=DATE(YEAR(SET!$I$11),MONTH(SET!$J$11),DAY(SET!$L$11)),MAX(0,F28-IF(I28<(G28+H28),0,(I28-(G28+H28)))),0),IF(E28>=DATE(YEAR(SET!$I$11),MONTH(SET!$J$11),DAY(SET!$L$11)),MAX(0,MIN(F28,SET!$L$3)-IF(I28<(G28+H28),0,(I28-(G28+H28)))),0))))))) -> 0 | N28: =IF(D28=0,IF(M28>0,IF((E28-C28)>=365,EDATE(E28,6),EDATE(K28,-6)),""),"") | O28: =IF(D28=0,IF(M28>0,IF((E28-C28)>=365,EDATE(E28,10),EDATE(K28,-2)),""),"") | P28: 연차 | Q28: 연차 | R28: 연차 | S28: 연차 | T28: 연차 | U28: 연차 | V28: 연차 | W28: 연차 | X28: 연차 | Y28: 연차 | Z28: 연차 | AA28: 연차 | AB28: 연차
P29: 45843 | Q29: 45844 | R29: 45845 | S29: 45846 | T29: 45902 | U29: 45985 | V29: 45986 | W29: 25/12/27 | X29: 26/01/22 | Y29: 26/03/30 | Z29: 26/03/31 | AA29: 26/04/07 | AB29: 26/04/08
B30: RN 경규록 | C30: 44263 | E30: =IF(DATEDIF(C30,M$2,"m")<1,"",IF(C30=0,"",IF(EDATE(C30,12)<IF($D30>0,$D30-1,M$2),EDATE(C30,DATEDIF(C30,IF($D30>0,$D30-1,M$2+1),"y")*12),EDATE(C30,DATEDIF(C30,IF($D30>0,$D30-1,M$2+1),"m"))))) -> 46089 | F30: =IF(E30="",0,IF(EDATE(C30,12)<=E30,15+IF((YEAR(E30)-YEAR($C30))>20,10,INT((YEAR(E30)-YEAR($C30)-1)/2)),0)) -> 17 | G30: =IF(E30="",0,IF(E30>=EDATE(C30,12),IF(E30<EDATE(C30,24),IF(C30<SET!$J$20,0,MIN(DATEDIF(C30,E30,"m"),11)),0),IF(D30>C30,IF(E30<=EDATE(C30,12),MIN(DATEDIF(C30,D30+1,"m"),11),0),MIN(DATEDIF(C30,E30,"m"),11)))) -> 0 | H30: 11.5 | I30: =COUNTIF(P30:BW30,SET!$C$15)*SET!$C$16+COUNTIF(P30:BW30,SET!$D$15)*SET!$D$16+COUNTIF(P30:BW30,SET!E$15)*SET!$E$16+COUNTIF(P30:BW30,SET!$F$15)*SET!$F$16+COUNTIF(P30:BW30,SET!$G$15)*SET!$G$16+COUNTIF(P30:BW30,SET!$H$15)*SET!$H$16+COUNTIF(P30:BW30,SET!$I$15)*SET!$I$16+COUNTIF(P30:BW30,)*SET!$K$16+COUNTIF(P30:BW30,SET!$M$15)*SET!$M$16 -> 2 | J30: =F30+G30+H30-I30 -> 26.5 | K30: =IF(E30="","",IF(AND(D30>C30,EDATE(IF(EDATE(C30,12)<D30,C30,E30),12)>D30),"퇴직정산",IF((E30-C30)>=365,EDATE(E30,12),EDATE(C30,24)))) -> 46454 | L30: =IF(K30="퇴직정산",J30,IF((M$2-C30)<365,"미확정",IF(M30="유예","유예",J30-M30))) -> 19.5 | M30: =IF(C30=0,0,IF(K30="퇴직정산",0,IF(J30<=0,0,IF(EDATE(C30,3)>M$2,"유예",IF(SET!$J$3="없음",0,IF(SET!$J$3="전부",IF(E30>=DATE(YEAR(SET!$I$11),MONTH(SET!$J$11),DAY(SET!$L$11)),MAX(0,F30-IF(I30<(G30+H30),0,(I30-(G30+H30)))),0),IF(E30>=DATE(YEAR(SET!$I$11),MONTH(SET!$J$11),DAY(SET!$L$11)),MAX(0,MIN(F30,SET!$L$3)-IF(I30<(G30+H30),0,(I30-(G30+H30)))),0))))))) -> 7 | N30: =IF(D30=0,IF(M30>0,IF((E30-C30)>=365,EDATE(E30,6),EDATE(K30,-6)),""),"") -> 46273 | O30: =IF(D30=0,IF(M30>0,IF((E30-C30)>=365,EDATE(E30,10),EDATE(K30,-2)),""),"") -> 46395 | P30: 연차 | Q30: 연차
P31: 26/02/17 | Q31: 26/03/20
B32: RN 김규리 | C32: 44928 | E32: =IF(DATEDIF(C32,M$2,"m")<1,"",IF(C32=0,"",IF(EDATE(C32,12)<IF($D32>0,$D32-1,M$2),EDATE(C32,DATEDIF(C32,IF($D32>0,$D32-1,M$2+1),"y")*12),EDATE(C32,DATEDIF(C32,IF($D32>0,$D32-1,M$2+1),"m"))))) -> 46024 | F32: =IF(E32="",0,IF(EDATE(C32,12)<=E32,15+IF((YEAR(E32)-YEAR($C32))>20,10,INT((YEAR(E32)-YEAR($C32)-1)/2)),0)) -> 16 | G32: =IF(E32="",0,IF(E32>=EDATE(C32,12),IF(E32<EDATE(C32,24),IF(C32<SET!$J$20,0,MIN(DATEDIF(C32,E32,"m"),11)),0),IF(D32>C32,IF(E32<=EDATE(C32,12),MIN(DATEDIF(C32,D32+1,"m"),11),0),MIN(DATEDIF(C32,E32,"m"),11)))) -> 0 | H32: 0 | I32: =COUNTIF(P32:BW32,SET!$C$15)*SET!$C$16+COUNTIF(P32:BW32,SET!$D$15)*SET!$D$16+COUNTIF(P32:BW32,SET!E$15)*SET!$E$16+COUNTIF(P32:BW32,SET!$F$15)*SET!$F$16+COUNTIF(P32:BW32,SET!$G$15)*SET!$G$16+COUNTIF(P32:BW32,SET!$H$15)*SET!$H$16+COUNTIF(P32:BW32,SET!$I$15)*SET!$I$16+COUNTIF(P32:BW32,)*SET!$K$16+COUNTIF(P32:BW32,SET!$M$15)*SET!$M$16 -> 6 | J32: =F32+G32+H32-I32 -> 10 | K32: =IF(E32="","",IF(AND(D32>C32,EDATE(IF(EDATE(C32,12)<D32,C32,E32),12)>D32),"퇴직정산",IF((E32-C32)>=365,EDATE(E32,12),EDATE(C32,24)))) -> 46389 | L32: =IF(K32="퇴직정산",J32,IF((M$2-C32)<365,"미확정",IF(M32="유예","유예",J32-M32))) -> 9 | M32: =IF(C32=0,0,IF(K32="퇴직정산",0,IF(J32<=0,0,IF(EDATE(C32,3)>M$2,"유예",IF(SET!$J$3="없음",0,IF(SET!$J$3="전부",IF(E32>=DATE(YEAR(SET!$I$11),MONTH(SET!$J$11),DAY(SET!$L$11)),MAX(0,F32-IF(I32<(G32+H32),0,(I32-(G32+H32)))),0),IF(E32>=DATE(YEAR(SET!$I$11),MONTH(SET!$J$11),DAY(SET!$L$11)),MAX(0,MIN(F32,SET!$L$3)-IF(I32<(G32+H32),0,(I32-(G32+H32)))),0))))))) -> 1 | N32: =IF(D32=0,IF(M32>0,IF((E32-C32)>=365,EDATE(E32,6),EDATE(K32,-6)),""),"") -> 46205 | O32: =IF(D32=0,IF(M32>0,IF((E32-C32)>=365,EDATE(E32,10),EDATE(K32,-2)),""),"") -> 46328 | P32: 연차 | Q32: 연차 | R32: 연차 | S32: 연차 | T32: 연차 | U32: 연차
P33: 25/12/18 | Q33: 25/12/19 | R33: 26/03/22 | S33: 26/03/23 | T33: 26/04/12 | U33: 26/04/13
B34: RN 김가현 | C34: 45236 | E34: =IF(DATEDIF(C34,M$2,"m")<1,"",IF(C34=0,"",IF(EDATE(C34,12)<IF($D34>0,$D34-1,M$2),EDATE(C34,DATEDIF(C34,IF($D34>0,$D34-1,M$2+1),"y")*12),EDATE(C34,DATEDIF(C34,IF($D34>0,$D34-1,M$2+1),"m"))))) -> 45967 | F34: =IF(E34="",0,IF(EDATE(C34,12)<=E34,15+IF((YEAR(E34)-YEAR($C34))>20,10,INT((YEAR(E34)-YEAR($C34)-1)/2)),0)) -> 15 | G34: =IF(E34="",0,IF(E34>=EDATE(C34,12),IF(E34<EDATE(C34,24),IF(C34<SET!$J$20,0,MIN(DATEDIF(C34,E34,"m"),11)),0),IF(D34>C34,IF(E34<=EDATE(C34,12),MIN(DATEDIF(C34,D34+1,"m"),11),0),MIN(DATEDIF(C34,E34,"m"),11)))) -> 0 | H34: -3.5 | I34: =COUNTIF(P34:BW34,SET!$C$15)*SET!$C$16+COUNTIF(P34:BW34,SET!$D$15)*SET!$D$16+COUNTIF(P34:BW34,SET!E$15)*SET!$E$16+COUNTIF(P34:BW34,SET!$F$15)*SET!$F$16+COUNTIF(P34:BW34,SET!$G$15)*SET!$G$16+COUNTIF(P34:BW34,SET!$H$15)*SET!$H$16+COUNTIF(P34:BW34,SET!$I$15)*SET!$I$16+COUNTIF(P34:BW34,)*SET!$K$16+COUNTIF(P34:BW34,SET!$M$15)*SET!$M$16 -> 5 | J34: =F34+G34+H34-I34 -> 6.5 | K34: =IF(E34="","",IF(AND(D34>C34,EDATE(IF(EDATE(C34,12)<D34,C34,E34),12)>D34),"퇴직정산",IF((E34-C34)>=365,EDATE(E34,12),EDATE(C34,24)))) -> 46332 | L34: =IF(K34="퇴직정산",J34,IF((M$2-C34)<365,"미확정",IF(M34="유예","유예",J34-M34))) -> 6.5 | M34: =IF(C34=0,0,IF(K34="퇴직정산",0,IF(J34<=0,0,IF(EDATE(C34,3)>M$2,"유예",IF(SET!$J$3="없음",0,IF(SET!$J$3="전부",IF(E34>=DATE(YEAR(SET!$I$11),MONTH(SET!$J$11),DAY(SET!$L$11)),MAX(0,F34-IF(I34<(G34+H34),0,(I34-(G34+H34)))),0),IF(E34>=DATE(YEAR(SET!$I$11),MONTH(SET!$J$11),DAY(SET!$L$11)),MAX(0,MIN(F34,SET!$L$3)-IF(I34<(G34+H34),0,(I34-(G34+H34)))),0))))))) -> 0 | N34: =IF(D34=0,IF(M34>0,IF((E34-C34)>=365,EDATE(E34,6),EDATE(K34,-6)),""),"") | O34: =IF(D34=0,IF(M34>0,IF((E34-C34)>=365,EDATE(E34,10),EDATE(K34,-2)),""),"") | P34: 연차 | Q34: 연차 | R34: 연차 | S34: 연차 | T34: 연차
P35: 45991 | Q35: 25/12/03 | R35: 25/12/04 | S35: 26/04/04 | T35: 26/04/09
B36: RN 이지원 | C36: 45278 | E36: =IF(DATEDIF(C36,M$2,"m")<1,"",IF(C36=0,"",IF(EDATE(C36,12)<IF($D36>0,$D36-1,M$2),EDATE(C36,DATEDIF(C36,IF($D36>0,$D36-1,M$2+1),"y")*12),EDATE(C36,DATEDIF(C36,IF($D36>0,$D36-1,M$2+1),"m"))))) -> 46009 | F36: =IF(E36="",0,IF(EDATE(C36,12)<=E36,15+IF((YEAR(E36)-YEAR($C36))>20,10,INT((YEAR(E36)-YEAR($C36)-1)/2)),0)) -> 15 | G36: =IF(E36="",0,IF(E36>=EDATE(C36,12),IF(E36<EDATE(C36,24),IF(C36<SET!$J$20,0,MIN(DATEDIF(C36,E36,"m"),11)),0),IF(D36>C36,IF(E36<=EDATE(C36,12),MIN(DATEDIF(C36,D36+1,"m"),11),0),MIN(DATEDIF(C36,E36,"m"),11)))) -> 0 | H36: 1 | I36: =COUNTIF(P36:BW36,SET!$C$15)*SET!$C$16+COUNTIF(P36:BW36,SET!$D$15)*SET!$D$16+COUNTIF(P36:BW36,SET!E$15)*SET!$E$16+COUNTIF(P36:BW36,SET!$F$15)*SET!$F$16+COUNTIF(P36:BW36,SET!$G$15)*SET!$G$16+COUNTIF(P36:BW36,SET!$H$15)*SET!$H$16+COUNTIF(P36:BW36,SET!$I$15)*SET!$I$16+COUNTIF(P36:BW36,)*SET!$K$16+COUNTIF(P36:BW36,SET!$M$15)*SET!$M$16 -> 4 | J36: =F36+G36+H36-I36 -> 12 | K36: =IF(E36="","",IF(AND(D36>C36,EDATE(IF(EDATE(C36,12)<D36,C36,E36),12)>D36),"퇴직정산",IF((E36-C36)>=365,EDATE(E36,12),EDATE(C36,24)))) -> 46374 | L36: =IF(K36="퇴직정산",J36,IF((M$2-C36)<365,"미확정",IF(M36="유예","유예",J36-M36))) -> 8 | M36: =IF(C36=0,0,IF(K36="퇴직정산",0,IF(J36<=0,0,IF(EDATE(C36,3)>M$2,"유예",IF(SET!$J$3="없음",0,IF(SET!$J$3="전부",IF(E36>=DATE(YEAR(SET!$I$11),MONTH(SET!$J$11),DAY(SET!$L$11)),MAX(0,F36-IF(I36<(G36+H36),0,(I36-(G36+H36)))),0),IF(E36>=DATE(YEAR(SET!$I$11),MONTH(SET!$J$11),DAY(SET!$L$11)),MAX(0,MIN(F36,SET!$L$3)-IF(I36<(G36+H36),0,(I36-(G36+H36)))),0))))))) -> 4 | N36: =IF(D36=0,IF(M36>0,IF((E36-C36)>=365,EDATE(E36,6),EDATE(K36,-6)),""),"") -> 46191 | O36: =IF(D36=0,IF(M36>0,IF((E36-C36)>=365,EDATE(E36,10),EDATE(K36,-2)),""),"") -> 46313 | P36: 연차 | Q36: 연차 | R36: 연차 | S36: 연차
P37: 46032 | Q37: 46115 | R37: 46116 | S37: 46117
B38: RN 양진주 | C38: 45432 | E38: =IF(DATEDIF(C38,M$2,"m")<1,"",IF(C38=0,"",IF(EDATE(C38,12)<IF($D38>0,$D38-1,M$2),EDATE(C38,DATEDIF(C38,IF($D38>0,$D38-1,M$2+1),"y")*12),EDATE(C38,DATEDIF(C38,IF($D38>0,$D38-1,M$2+1),"m"))))) -> 45797 | F38: =IF(E38="",0,IF(EDATE(C38,12)<=E38,15+IF((YEAR(E38)-YEAR($C38))>20,10,INT((YEAR(E38)-YEAR($C38)-1)/2)),0)) -> 15 | G38: =IF(E38="",0,IF(E38>=EDATE(C38,12),IF(E38<EDATE(C38,24),IF(C38<SET!$J$20,0,MIN(DATEDIF(C38,E38,"m"),11)),0),IF(D38>C38,IF(E38<=EDATE(C38,12),MIN(DATEDIF(C38,D38+1,"m"),11),0),MIN(DATEDIF(C38,E38,"m"),11)))) -> 11 | I38: =COUNTIF(P38:BW38,SET!$C$15)*SET!$C$16+COUNTIF(P38:BW38,SET!$D$15)*SET!$D$16+COUNTIF(P38:BW38,SET!E$15)*SET!$E$16+COUNTIF(P38:BW38,SET!$F$15)*SET!$F$16+COUNTIF(P38:BW38,SET!$G$15)*SET!$G$16+COUNTIF(P38:BW38,SET!$H$15)*SET!$H$16+COUNTIF(P38:BW38,SET!$I$15)*SET!$I$16+COUNTIF(P38:BW38,)*SET!$K$16+COUNTIF(P38:BW38,SET!$M$15)*SET!$M$16 -> 24 | J38: =F38+G38+H38-I38 -> 2 | K38: =IF(E38="","",IF(AND(D38>C38,EDATE(IF(EDATE(C38,12)<D38,C38,E38),12)>D38),"퇴직정산",IF((E38-C38)>=365,EDATE(E38,12),EDATE(C38,24)))) -> 46162 | L38: =IF(K38="퇴직정산",J38,IF((M$2-C38)<365,"미확정",IF(M38="유예","유예",J38-M38))) -> 2 | M38: =IF(C38=0,0,IF(K38="퇴직정산",0,IF(J38<=0,0,IF(EDATE(C38,3)>M$2,"유예",IF(SET!$J$3="없음",0,IF(SET!$J$3="전부",IF(E38>=DATE(YEAR(SET!$I$11),MONTH(SET!$J$11),DAY(SET!$L$11)),MAX(0,F38-IF(I38<(G38+H38),0,(I38-(G38+H38)))),0),IF(E38>=DATE(YEAR(SET!$I$11),MONTH(SET!$J$11),DAY(SET!$L$11)),MAX(0,MIN(F38,SET!$L$3)-IF(I38<(G38+H38),0,(I38-(G38+H38)))),0))))))) -> 0 | N38: =IF(D38=0,IF(M38>0,IF((E38-C38)>=365,EDATE(E38,6),EDATE(K38,-6)),""),"") | O38: =IF(D38=0,IF(M38>0,IF((E38-C38)>=365,EDATE(E38,10),EDATE(K38,-2)),""),"") | P38: 연차 | Q38: 연차 | R38: 연차 | S38: 연차 | T38: 연차 | U38: 연차 | V38: 연차 | W38: 연차 | X38: 연차 | Y38: 연차 | Z38: 연차 | AA38: 연차 | AB38: 연차 | AC38: 연차 | AD38: 연차 | AE38: 연차 | AF38: 연차 | AG38: 연차 | AH38: 연차 | AI38: 연차 | AJ38: 연차 | AK38: 연차 | AL38: 연차 | AM38: 연차
P39: 45500 | Q39: 45501 | R39: 45514 | S39: 45648 | T39: 45697 | U39: 45752 | V39: 45859 | W39: 45860 | X39: 45861 | Y39: 45865 | Z39: 45866 | AA39: 45867 | AB39: 45879 | AC39: 45914 | AD39: 45915 | AE39: 45990 | AF39: 45991 | AG39: 25/12/09 | AH39: 25/12/10 | AI39: 25/12/11 | AJ39: 26/01/07 | AK39: 26/04/14 | AL39: 26/04/15 | AM39: 26/04/23
B40: RN 최다솜 | C40: 44144 | E40: =IF(DATEDIF(C40,M$2,"m")<1,"",IF(C40=0,"",IF(EDATE(C40,12)<IF($D40>0,$D40-1,M$2),EDATE(C40,DATEDIF(C40,IF($D40>0,$D40-1,M$2+1),"y")*12),EDATE(C40,DATEDIF(C40,IF($D40>0,$D40-1,M$2+1),"m"))))) -> 45970 | F40: =IF(E40="",0,IF(EDATE(C40,12)<=E40,15+IF((YEAR(E40)-YEAR($C40))>20,10,INT((YEAR(E40)-YEAR($C40)-1)/2)),0)) -> 17 | G40: =IF(E40="",0,IF(E40>=EDATE(C40,12),IF(E40<EDATE(C40,24),IF(C40<SET!$J$20,0,MIN(DATEDIF(C40,E40,"m"),11)),0),IF(D40>C40,IF(E40<=EDATE(C40,12),MIN(DATEDIF(C40,D40+1,"m"),11),0),MIN(DATEDIF(C40,E40,"m"),11)))) -> 0 | H40: 13 | I40: =COUNTIF(P40:BW40,SET!$C$15)*SET!$C$16+COUNTIF(P40:BW40,SET!$D$15)*SET!$D$16+COUNTIF(P40:BW40,SET!E$15)*SET!$E$16+COUNTIF(P40:BW40,SET!$F$15)*SET!$F$16+COUNTIF(P40:BW40,SET!$G$15)*SET!$G$16+COUNTIF(P40:BW40,SET!$H$15)*SET!$H$16+COUNTIF(P40:BW40,SET!$I$15)*SET!$I$16+COUNTIF(P40:BW40,)*SET!$K$16+COUNTIF(P40:BW40,SET!$M$15)*SET!$M$16 -> 23 | J40: =F40+G40+H40-I40 -> 7 | K40: =IF(E40="","",IF(AND(D40>C40,EDATE(IF(EDATE(C40,12)<D40,C40,E40),12)>D40),"퇴직정산",IF((E40-C40)>=365,EDATE(E40,12),EDATE(C40,24)))) -> 46335 | L40: =IF(K40="퇴직정산",J40,IF((M$2-C40)<365,"미확정",IF(M40="유예","유예",J40-M40))) -> 7 | M40: =IF(C40=0,0,IF(K40="퇴직정산",0,IF(J40<=0,0,IF(EDATE(C40,3)>M$2,"유예",IF(SET!$J$3="없음",0,IF(SET!$J$3="전부",IF(E40>=DATE(YEAR(SET!$I$11),MONTH(SET!$J$11),DAY(SET!$L$11)),MAX(0,F40-IF(I40<(G40+H40),0,(I40-(G40+H40)))),0),IF(E40>=DATE(YEAR(SET!$I$11),MONTH(SET!$J$11),DAY(SET!$L$11)),MAX(0,MIN(F40,SET!$L$3)-IF(I40<(G40+H40),0,(I40-(G40+H40)))),0))))))) -> 0 | N40: =IF(D40=0,IF(M40>0,IF((E40-C40)>=365,EDATE(E40,6),EDATE(K40,-6)),""),"") | O40: =IF(D40=0,IF(M40>0,IF((E40-C40)>=365,EDATE(E40,10),EDATE(K40,-2)),""),"") | P40: 연차 | Q40: 연차 | R40: 연차 | S40: 연차 | T40: 연차 | U40: 연차 | V40: 연차 | W40: 연차 | X40: 연차 | Y40: 연차 | Z40: 연차 | AA40: 연차 | AB40: 연차 | AC40: 연차 | AD40: 연차 | AE40: 연차 | AF40: 연차 | AG40: 연차 | AH40: 연차 | AI40: 연차 | AJ40: 연차 | AK40: 연차 | AL40: 연차
P41: 46125 | Q41: 46126 | R41: 46127 | S41: 46128 | T41: 46129 | U41: 46132 | V41: 46133 | W41: 46134 | X41: 46135 | Y41: 46136 | Z41: 46139 | AA41: 46140 | AB41: 46141 | AC41: 46142 | AD41: 46146 | AE41: 46148 | AF41: 46149 | AG41: 46150 | AH41: 46153 | AI41: 46154 | AJ41: 46155 | AK41: 46156 | AL41: 46157
B42: RN 이민아 | C42: 45187 | E42: =IF(DATEDIF(C42,M$2,"m")<1,"",IF(C42=0,"",IF(EDATE(C42,12)<IF($D42>0,$D42-1,M$2),EDATE(C42,DATEDIF(C42,IF($D42>0,$D42-1,M$2+1),"y")*12),EDATE(C42,DATEDIF(C42,IF($D42>0,$D42-1,M$2+1),"m"))))) -> 45918 | F42: =IF(E42="",0,IF(EDATE(C42,12)<=E42,15+IF((YEAR(E42)-YEAR($C42))>20,10,INT((YEAR(E42)-YEAR($C42)-1)/2)),0)) -> 15 | G42: =IF(E42="",0,IF(E42>=EDATE(C42,12),IF(E42<EDATE(C42,24),IF(C42<SET!$J$20,0,MIN(DATEDIF(C42,E42,"m"),11)),0),IF(D42>C42,IF(E42<=EDATE(C42,12),MIN(DATEDIF(C42,D42+1,"m"),11),0),MIN(DATEDIF(C42,E42,"m"),11)))) -> 0 | H42: 8 | I42: =COUNTIF(P42:BW42,SET!$C$15)*SET!$C$16+COUNTIF(P42:BW42,SET!$D$15)*SET!$D$16+COUNTIF(P42:BW42,SET!E$15)*SET!$E$16+COUNTIF(P42:BW42,SET!$F$15)*SET!$F$16+COUNTIF(P42:BW42,SET!$G$15)*SET!$G$16+COUNTIF(P42:BW42,SET!$H$15)*SET!$H$16+COUNTIF(P42:BW42,SET!$I$15)*SET!$I$16+COUNTIF(P42:BW42,)*SET!$K$16+COUNTIF(P42:BW42,SET!$M$15)*SET!$M$16 -> 15 | J42: =F42+G42+H42-I42 -> 8 | K42: =IF(E42="","",IF(AND(D42>C42,EDATE(IF(EDATE(C42,12)<D42,C42,E42),12)>D42),"퇴직정산",IF((E42-C42)>=365,EDATE(E42,12),EDATE(C42,24)))) -> 46283 | L42: =IF(K42="퇴직정산",J42,IF((M$2-C42)<365,"미확정",IF(M42="유예","유예",J42-M42))) -> 8 | M42: =IF(C42=0,0,IF(K42="퇴직정산",0,IF(J42<=0,0,IF(EDATE(C42,3)>M$2,"유예",IF(SET!$J$3="없음",0,IF(SET!$J$3="전부",IF(E42>=DATE(YEAR(SET!$I$11),MONTH(SET!$J$11),DAY(SET!$L$11)),MAX(0,F42-IF(I42<(G42+H42),0,(I42-(G42+H42)))),0),IF(E42>=DATE(YEAR(SET!$I$11),MONTH(SET!$J$11),DAY(SET!$L$11)),MAX(0,MIN(F42,SET!$L$3)-IF(I42<(G42+H42),0,(I42-(G42+H42)))),0))))))) -> 0 | N42: =IF(D42=0,IF(M42>0,IF((E42-C42)>=365,EDATE(E42,6),EDATE(K42,-6)),""),"") | O42: =IF(D42=0,IF(M42>0,IF((E42-C42)>=365,EDATE(E42,10),EDATE(K42,-2)),""),"") | P42: 연차 | Q42: 연차 | R42: 연차 | S42: 연차 | T42: 연차 | U42: 연차 | V42: 연차 | W42: 연차 | X42: 연차 | Y42: 연차 | Z42: 연차 | AA42: 연차 | AB42: 연차 | AC42: 연차 | AD42: 연차
P43: 45939 | Q43: 45940 | R43: 45941 | S43: 45987 | T43: 45988 | U43: 45989 | V43: 25/12/20 | W43: 25/12/21 | X43: 26/01/12 | Y43: 26/01/13 | Z43: 26/02/04 | AA43: 26/03/28 | AB43: 26/04/07 | AC43: 26/04/08 | AD43: 26/04/09
...

Sheet 25년도 정산DATA(재직자)
R1: [근태목록 수정하기] | S1: https://blog.naver.com/bgheaven/221375853579
J2: 현재기준일자 | M2: =TODAY() -> 46157 | R2: [조건부서식 설명보기] | S2: https://blog.naver.com/bgheaven/221386977948
A4: 부서 | B4: 이 름 | C4: 입사일자 | D4: 정산일자 | E4: 연차유급휴가 발생현황 (현재기준) | I4: 사용 누계 | J4: 사용 가능 연차 | K4: 연차유급휴가 정산 | N4: 사용권고통보일자 1차 촉진 / 2차 촉진 | P4: 연차유급휴가 사용 및 근태 기록부
E5: 사용시작일 (발생확정다음날) | F5: 연차 일수 | G5: 신입 연차 | H5: 전년도 이월 연차 | K5: 정산시점 (사용종료다음날) | L5: 정산 일수 | M5: 사용 촉진 | N5: 근로자 자율 사용계획서 제출 | O5: 사용자의 강제 사용일자 통보 | P5: 1 | Q5: 2 | R5: 3 | S5: 4 | T5: 5 | U5: 6 | V5: 7 | W5: 8 | X5: 9 | Y5: 10 | Z5: 11 | AA5: 12 | AB5: 13 | AC5: 14 | AD5: 15 | AE5: 16 | AF5: 17 | AG5: 18 | AH5: 19 | AI5: 20 | AJ5: 21 | AK5: 22 | AL5: 23 | AM5: 24 | AN5: 25 | AO5: 26 | AP5: 27 | AQ5: 28 | AR5: 29 | AS5: 30 | AT5: 31 | AU5: 32 | AV5: 33 | AW5: 34 | AX5: 35 | AY5: 36 | AZ5: 37 | BA5: 38 | BB5: 39 | BC5: 40 | BD5: 41 | BE5: 42 | BF5: 43 | BG5: 44 | BH5: 45 | BI5: 46 | BJ5: 47 | BK5: 48 | BL5: 49 | BM5: 50 | BN5: 51 | BO5: 52 | BP5: 53 | BQ5: 54 | BR5: 55 | BS5: 56 | BT5: 57 | BU5: 58 | BV5: 59 | BW5: 60
A6: 5A병동 | B6: 병동지원 박세빈 | C6: 44927 | D6: 45658 | E6: =IF(DATEDIF(C6,M$2,"m")<1,"",IF(C6=0,"",IF(EDATE(C6,12)<IF($D6>0,$D6-1,M$2),EDATE(C6,DATEDIF(C6,IF($D6>0,$D6-1,M$2+1),"y")*12),EDATE(C6,DATEDIF(C6,IF($D6>0,$D6-1,M$2+1),"m"))))) -> 45292 | F6: =IF(E6="",0,IF(EDATE(C6,12)<=E6,15+IF((YEAR(E6)-YEAR($C6))>20,10,INT((YEAR(E6)-YEAR($C6)-1)/2)),0)) -> 15 | G6: =IF(E6="",0,IF(E6>=EDATE(C6,12),IF(E6<EDATE(C6,24),IF(C6<SET!$J$20,0,MIN(DATEDIF(C6,E6,"m"),11)),0),IF(D6>C6,IF(E6<=EDATE(C6,12),MIN(DATEDIF(C6,D6+1,"m"),11),0),MIN(DATEDIF(C6,E6,"m"),11)))) -> 11 | I6: =COUNTIF(P6:BW6,SET!$C$15)*SET!$C$16+COUNTIF(P6:BW6,SET!$D$15)*SET!$D$16+COUNTIF(P6:BW6,SET!E$15)*SET!$E$16+COUNTIF(P6:BW6,SET!$F$15)*SET!$F$16+COUNTIF(P6:BW6,SET!$G$15)*SET!$G$16+COUNTIF(P6:BW6,SET!$H$15)*SET!$H$16+COUNTIF(P6:BW6,SET!$I$15)*SET!$I$16+COUNTIF(P6:BW6,)*SET!$K$16+COUNTIF(P6:BW6,SET!$M$15)*SET!$M$16 -> 19.5 | J6: =F6+G6+H6-I6 -> 6.5 | K6: =IF(E6="","",IF(AND(D6>C6,EDATE(IF(EDATE(C6,12)<D6,C6,E6),12)>D6),"퇴직정산",IF((E6-C6)>=365,EDATE(E6,12),EDATE(C6,24)))) -> 45658 | L6: =IF(K6="퇴직정산",J6,IF((M$2-C6)<365,"미확정",IF(M6="유예","유예",J6-M6))) -> 6.5 | M6: =IF(C6=0,0,IF(K6="퇴직정산",0,IF(J6<=0,0,IF(EDATE(C6,3)>M$2,"유예",IF(SET!$J$3="없음",0,IF(SET!$J$3="전부",IF(E6>=DATE(YEAR(SET!$I$11),MONTH(SET!$J$11),DAY(SET!$L$11)),MAX(0,F6-IF(I6<(G6+H6),0,(I6-(G6+H6)))),0),IF(E6>=DATE(YEAR(SET!$I$11),MONTH(SET!$J$11),DAY(SET!$L$11)),MAX(0,MIN(F6,SET!$L$3)-IF(I6<(G6+H6),0,(I6-(G6+H6)))),0))))))) -> 0 | N6: =IF(D6=0,IF(M6>0,IF((E6-C6)>=365,EDATE(E6,6),EDATE(K6,-6)),""),"") | O6: =IF(D6=0,IF(M6>0,IF((E6-C6)>=365,EDATE(E6,10),EDATE(K6,-2)),""),"") | P6: 연차 | Q6: 반차 | R6: 반차 | S6: 연차 | T6: 연차 | U6: 연차 | V6: 연차 | W6: 연차 | X6: 연차 | Y6: 연차 | Z6: 연차 | AA6: 연차 | AB6: 연차 | AC6: 연차 | AD6: 연차 | AE6: 연차 | AF6: 반차 | AG6: 연차 | AH6: 연차 | AI6: 연차 | AJ6: 연차
P7: 44981 | Q7: 44999 | R7: 45020 | S7: 45124 | T7: 45159 | U7: 45182 | V7: 45183 | W7: 45231 | X7: 45232 | Y7: 45233 | Z7: 45271 | AA7: 45376 | AB7: 45404 | AC7: 45474 | AD7: 45491 | AE7: 45520 | AF7: 45560 | AG7: 45561 | AH7: 45589 | AI7: 45618 | AJ7: 45625
A8: 총무과 | B8: 장윤정 | C8: 44197 | D8: 45658 | E8: =IF(DATEDIF(C8,M$2,"m")<1,"",IF(C8=0,"",IF(EDATE(C8,12)<IF($D8>0,$D8-1,M$2),EDATE(C8,DATEDIF(C8,IF($D8>0,$D8-1,M$2+1),"y")*12),EDATE(C8,DATEDIF(C8,IF($D8>0,$D8-1,M$2+1),"m"))))) -> 45292 | F8: =IF(E8="",0,IF(EDATE(C8,12)<=E8,15+IF((YEAR(E8)-YEAR($C8))>20,10,INT((YEAR(E8)-YEAR($C8)-1)/2)),0)) -> 16 | G8: =IF(E8="",0,IF(E8>=EDATE(C8,12),IF(E8<EDATE(C8,24),IF(C8<SET!$J$20,0,MIN(DATEDIF(C8,E8,"m"),11)),0),IF(D8>C8,IF(E8<=EDATE(C8,12),MIN(DATEDIF(C8,D8+1,"m"),11),0),MIN(DATEDIF(C8,E8,"m"),11)))) -> 0 | H8: 0 | I8: =COUNTIF(P8:BW8,SET!$C$15)*SET!$C$16+COUNTIF(P8:BW8,SET!$D$15)*SET!$D$16+COUNTIF(P8:BW8,SET!E$15)*SET!$E$16+COUNTIF(P8:BW8,SET!$F$15)*SET!$F$16+COUNTIF(P8:BW8,SET!$G$15)*SET!$G$16+COUNTIF(P8:BW8,SET!$H$15)*SET!$H$16+COUNTIF(P8:BW8,SET!$I$15)*SET!$I$16+COUNTIF(P8:BW8,)*SET!$K$16+COUNTIF(P8:BW8,SET!$M$15)*SET!$M$16 -> 16 | J8: =F8+G8+H8-I8 -> 0 | K8: =IF(E8="","",IF(AND(D8>C8,EDATE(IF(EDATE(C8,12)<D8,C8,E8),12)>D8),"퇴직정산",IF((E8-C8)>=365,EDATE(E8,12),EDATE(C8,24)))) -> 45658 | L8: =IF(K8="퇴직정산",J8,IF((M$2-C8)<365,"미확정",IF(M8="유예","유예",J8-M8))) -> 0 | M8: =IF(C8=0,0,IF(K8="퇴직정산",0,IF(J8<=0,0,IF(EDATE(C8,3)>M$2,"유예",IF(SET!$J$3="없음",0,IF(SET!$J$3="전부",IF(E8>=DATE(YEAR(SET!$I$11),MONTH(SET!$J$11),DAY(SET!$L$11)),MAX(0,F8-IF(I8<(G8+H8),0,(I8-(G8+H8)))),0),IF(E8>=DATE(YEAR(SET!$I$11),MONTH(SET!$J$11),DAY(SET!$L$11)),MAX(0,MIN(F8,SET!$L$3)-IF(I8<(G8+H8),0,(I8-(G8+H8)))),0))))))) -> 0 | N8: =IF(D8=0,IF(M8>0,IF((E8-C8)>=365,EDATE(E8,6),EDATE(K8,-6)),""),"") | O8: =IF(D8=0,IF(M8>0,IF((E8-C8)>=365,EDATE(E8,10),EDATE(K8,-2)),""),"") | P8: 연차 | Q8: 연차 | R8: 연차 | S8: 연차 | T8: 연차 | U8: 연차 | V8: 연차 | W8: 연차 | X8: 연차 | Y8: 연차 | Z8: 연차 | AA8: 연차 | AB8: 연차 | AC8: 연차 | AD8: 연차 | AE8: 연차
P9: 45327 | Q9: 45328 | R9: 45329 | S9: 45330 | T9: 45369 | U9: 45370 | V9: 45371 | W9: 45372 | X9: 45373 | Y9: 45432 | Z9: 45433 | AA9: 45434 | AB9: 45435 | AC9: 45436 | AD9: 45509 | AE9: 45510
A10: 3병동 | B10: RN 김규리 | C10: 44928 | D10: 45659 | E10: =IF(DATEDIF(C10,M$2,"m")<1,"",IF(C10=0,"",IF(EDATE(C10,12)<IF($D10>0,$D10-1,M$2),EDATE(C10,DATEDIF(C10,IF($D10>0,$D10-1,M$2+1),"y")*12),EDATE(C10,DATEDIF(C10,IF($D10>0,$D10-1,M$2+1),"m"))))) -> 45293 | F10: =IF(E10="",0,IF(EDATE(C10,12)<=E10,15+IF((YEAR(E10)-YEAR($C10))>20,10,INT((YEAR(E10)-YEAR($C10)-1)/2)),0)) -> 15 | G10: =IF(E10="",0,IF(E10>=EDATE(C10,12),IF(E10<EDATE(C10,24),IF(C10<SET!$J$20,0,MIN(DATEDIF(C10,E10,"m"),11)),0),IF(D10>C10,IF(E10<=EDATE(C10,12),MIN(DATEDIF(C10,D10+1,"m"),11),0),MIN(DATEDIF(C10,E10,"m"),11)))) -> 11 | I10: =COUNTIF(P10:BW10,SET!$C$15)*SET!$C$16+COUNTIF(P10:BW10,SET!$D$15)*SET!$D$16+COUNTIF(P10:BW10,SET!E$15)*SET!$E$16+COUNTIF(P10:BW10,SET!$F$15)*SET!$F$16+COUNTIF(P10:BW10,SET!$G$15)*SET!$G$16+COUNTIF(P10:BW10,SET!$H$15)*SET!$H$16+COUNTIF(P10:BW10,SET!$I$15)*SET!$I$16+COUNTIF(P10:BW10,)*SET!$K$16+COUNTIF(P10:BW10,SET!$M$15)*SET!$M$16 -> 25 | J10: =F10+G10+H10-I10 -> 1 | K10: =IF(E10="","",IF(AND(D10>C10,EDATE(IF(EDATE(C10,12)<D10,C10,E10),12)>D10),"퇴직정산",IF((E10-C10)>=365,EDATE(E10,12),EDATE(C10,24)))) -> 45659 | L10: =IF(K10="퇴직정산",J10,IF((M$2-C10)<365,"미확정",IF(M10="유예","유예",J10-M10))) -> 1 | M10: =IF(C10=0,0,IF(K10="퇴직정산",0,IF(J10<=0,0,IF(EDATE(C10,3)>M$2,"유예",IF(SET!$J$3="없음",0,IF(SET!$J$3="전부",IF(E10>=DATE(YEAR(SET!$I$11),MONTH(SET!$J$11),DAY(SET!$L$11)),MAX(0,F10-IF(I10<(G10+H10),0,(I10-(G10+H10)))),0),IF(E10>=DATE(YEAR(SET!$I$11),MONTH(SET!$J$11),DAY(SET!$L$11)),MAX(0,MIN(F10,SET!$L$3)-IF(I10<(G10+H10),0,(I10-(G10+H10)))),0))))))) -> 0 | N10: =IF(D10=0,IF(M10>0,IF((E10-C10)>=365,EDATE(E10,6),EDATE(K10,-6)),""),"") | O10: =IF(D10=0,IF(M10>0,IF((E10-C10)>=365,EDATE(E10,10),EDATE(K10,-2)),""),"") | P10: 연차 | Q10: 연차 | R10: 연차 | S10: 연차 | T10: 연차 | U10: 연차 | V10: 연차 | W10: 연차 | X10: 연차 | Y10: 연차 | Z10: 연차 | AA10: 연차 | AB10: 연차 | AC10: 연차 | AD10: 연차 | AE10: 연차 | AF10: 연차 | AG10: 연차 | AH10: 연차 | AI10: 연차 | AJ10: 연차 | AK10: 연차 | AL10: 연차 | AM10: 연차 | AN10: 연차
P11: 45099 | Q11: 45141 | R11: 45142 | S11: 45235 | T11: 45252 | U11: 45253 | V11: 45254 | W11: 45292 | X11: 45293 | Y11: 45333 | Z11: 45356 | AA11: 45383 | AB11: 45384 | AC11: 45407 | AD11: 45446 | AE11: 45481 | AF11: 45482 | AG11: 45493 | AH11: 45494 | AI11: 45509 | AJ11: 45510 | AK11: 45525 | AL11: 45526 | AM11: 45598 | AN11: 45626
A12: 5A병동 | B12: RN 사공금옥 | C12: 43467 | D12: 45659 | E12: =IF(DATEDIF(C12,M$2,"m")<1,"",IF(C12=0,"",IF(EDATE(C12,12)<IF($D12>0,$D12-1,M$2),EDATE(C12,DATEDIF(C12,IF($D12>0,$D12-1,M$2+1),"y")*12),EDATE(C12,DATEDIF(C12,IF($D12>0,$D12-1,M$2+1),"m"))))) -> 45293 | F12: =IF(E12="",0,IF(EDATE(C12,12)<=E12,15+IF((YEAR(E12)-YEAR($C12))>20,10,INT((YEAR(E12)-YEAR($C12)-1)/2)),0)) -> 17 | G12: =IF(E12="",0,IF(E12>=EDATE(C12,12),IF(E12<EDATE(C12,24),IF(C12<SET!$J$20,0,MIN(DATEDIF(C12,E12,"m"),11)),0),IF(D12>C12,IF(E12<=EDATE(C12,12),MIN(DATEDIF(C12,D12+1,"m"),11),0),MIN(DATEDIF(C12,E12,"m"),11)))) -> 0 | H12: 9 | I12: =COUNTIF(P12:BW12,SET!$C$15)*SET!$C$16+COUNTIF(P12:BW12,SET!$D$15)*SET!$D$16+COUNTIF(P12:BW12,SET!E$15)*SET!$E$16+COUNTIF(P12:BW12,SET!$F$15)*SET!$F$16+COUNTIF(P12:BW12,SET!$G$15)*SET!$G$16+COUNTIF(P12:BW12,SET!$H$15)*SET!$H$16+COUNTIF(P12:BW12,SET!$I$15)*SET!$I$16+COUNTIF(P12:BW12,)*SET!$K$16+COUNTIF(P12:BW12,SET!$M$15)*SET!$M$16 -> 20 | J12: =F12+G12+H12-I12 -> 6 | K12: =IF(E12="","",IF(AND(D12>C12,EDATE(IF(EDATE(C12,12)<D12,C12,E12),12)>D12),"퇴직정산",IF((E12-C12)>=365,EDATE(E12,12),EDATE(C12,24)))) -> 45659 | L12: =IF(K12="퇴직정산",J12,IF((M$2-C12)<365,"미확정",IF(M12="유예","유예",J12-M12))) -> 6 | M12: =IF(C12=0,0,IF(K12="퇴직정산",0,IF(J12<=0,0,IF(EDATE(C12,3)>M$2,"유예",IF(SET!$J$3="없음",0,IF(SET!$J$3="전부",IF(E12>=DATE(YEAR(SET!$I$11),MONTH(SET!$J$11),DAY(SET!$L$11)),MAX(0,F12-IF(I12<(G12+H12),0,(I12-(G12+H12)))),0),IF(E12>=DATE(YEAR(SET!$I$11),MONTH(SET!$J$11),DAY(SET!$L$11)),MAX(0,MIN(F12,SET!$L$3)-IF(I12<(G12+H12),0,(I12-(G12+H12)))),0))))))) -> 0 | N12: =IF(D12=0,IF(M12>0,IF((E12-C12)>=365,EDATE(E12,6),EDATE(K12,-6)),""),"") | O12: =IF(D12=0,IF(M12>0,IF((E12-C12)>=365,EDATE(E12,10),EDATE(K12,-2)),""),"") | P12: 연차 | Q12: 연차 | R12: 연차 | S12: 연차 | T12: 연차 | U12: 연차 | V12: 연차 | W12: 연차 | X12: 연차 | Y12: 연차 | Z12: 연차 | AA12: 연차 | AB12: 연차 | AC12: 연차 | AD12: 연차 | AE12: 연차 | AF12: 연차 | AG12: 연차 | AH12: 연차 | AI12: 연차
P13: 45516 | Q13: 45517 | R13: 45518 | S13: 45520 | T13: 45523 | U13: 45524 | V13: 45525 | W13: 45526 | X13: 45527 | Y13: 45530 | Z13: 45531 | AA13: 45532 | AB13: 45533 | AC13: 45534 | AD13: 45560 | AE13: 45562 | AF13: 45565 | AG13: 45576 | AH13: 45593 | AI13: 45618
A14: 수술실 | B14: CN 김혜란 | C14: 43102 | D14: 45659 | E14: =IF(DATEDIF(C14,M$2,"m")<1,"",IF(C14=0,"",IF(EDATE(C14,12)<IF($D14>0,$D14-1,M$2),EDATE(C14,DATEDIF(C14,IF($D14>0,$D14-1,M$2+1),"y")*12),EDATE(C14,DATEDIF(C14,IF($D14>0,$D14-1,M$2+1),"m"))))) -> 45293 | F14: =IF(E14="",0,IF(EDATE(C14,12)<=E14,15+IF((YEAR(E14)-YEAR($C14))>20,10,INT((YEAR(E14)-YEAR($C14)-1)/2)),0)) -> 17 | G14: =IF(E14="",0,IF(E14>=EDATE(C14,12),IF(E14<EDATE(C14,24),IF(C14<SET!$J$20,0,MIN(DATEDIF(C14,E14,"m"),11)),0),IF(D14>C14,IF(E14<=EDATE(C14,12),MIN(DATEDIF(C14,D14+1,"m"),11),0),MIN(DATEDIF(C14,E14,"m"),11)))) -> 0 | H14: 4 | I14: =COUNTIF(P14:BW14,SET!$C$15)*SET!$C$16+COUNTIF(P14:BW14,SET!$D$15)*SET!$D$16+COUNTIF(P14:BW14,SET!E$15)*SET!$E$16+COUNTIF(P14:BW14,SET!$F$15)*SET!$F$16+COUNTIF(P14:BW14,SET!$G$15)*SET!$G$16+COUNTIF(P14:BW14,SET!$H$15)*SET!$H$16+COUNTIF(P14:BW14,SET!$I$15)*SET!$I$16+COUNTIF(P14:BW14,)*SET!$K$16+COUNTIF(P14:BW14,SET!$M$15)*SET!$M$16 -> 19.5 | J14: =F14+G14+H14-I14 -> 1.5 | K14: =IF(E14="","",IF(AND(D14>C14,EDATE(IF(EDATE(C14,12)<D14,C14,E14),12)>D14),"퇴직정산",IF((E14-C14)>=365,EDATE(E14,12),EDATE(C14,24)))) -> 45659 | L14: =IF(K14="퇴직정산",J14,IF((M$2-C14)<365,"미확정",IF(M14="유예","유예",J14-M14))) -> 1.5 | M14: =IF(C14=0,0,IF(K14="퇴직정산",0,IF(J14<=0,0,IF(EDATE(C14,3)>M$2,"유예",IF(SET!$J$3="없음",0,IF(SET!$J$3="전부",IF(E14>=DATE(YEAR(SET!$I$11),MONTH(SET!$J$11),DAY(SET!$L$11)),MAX(0,F14-IF(I14<(G14+H14),0,(I14-(G14+H14)))),0),IF(E14>=DATE(YEAR(SET!$I$11),MONTH(SET!$J$11),DAY(SET!$L$11)),MAX(0,MIN(F14,SET!$L$3)-IF(I14<(G14+H14),0,(I14-(G14+H14)))),0))))))) -> 0 | N14: =IF(D14=0,IF(M14>0,IF((E14-C14)>=365,EDATE(E14,6),EDATE(K14,-6)),""),"") | O14: =IF(D14=0,IF(M14>0,IF((E14-C14)>=365,EDATE(E14,10),EDATE(K14,-2)),""),"") | P14: 연차 | Q14: 연차 | R14: 연차 | S14: 반차 | T14: 반차 | U14: 반차 | V14: 반차 | W14: 연차 | X14: 연차 | Y14: 반차 | Z14: 반차 | AA14: 연차 | AB14: 연차 | AC14: 연차 | AD14: 연차 | AE14: 반차 | AF14: 연차 | AG14: 반차 | AH14: 반차 | AI14: 연차 | AJ14: 연차 | AK14: 반차 | AL14: 반차 | AM14: 반차 | AN14: 반차 | AO14: 연차
P15: 45261 | Q15: 45273 | R15: 45278 | S15: 45341 | T15: 45350 | U15: 45355 | V15: 45400 | W15: 45457 | X15: 45462 | Y15: 45470 | Z15: 45477 | AA15: 45497 | AB15: 45498 | AC15: 45499 | AD15: 45502 | AE15: 45520 | AF15: 45527 | AG15: 45539 | AH15: 45546 | AI15: 45559 | AJ15: 45560 | AK15: 45579 | AL15: 45597 | AM15: 45600 | AN15: 45601 | AO15: 45618
A16: 5B병동 | B16: RN 배랑경 | C16: 43836 | D16: 45663 | E16: =IF(DATEDIF(C16,M$2,"m")<1,"",IF(C16=0,"",IF(EDATE(C16,12)<IF($D16>0,$D16-1,M$2),EDATE(C16,DATEDIF(C16,IF($D16>0,$D16-1,M$2+1),"y")*12),EDATE(C16,DATEDIF(C16,IF($D16>0,$D16-1,M$2+1),"m"))))) -> 45297 | F16: =IF(E16="",0,IF(EDATE(C16,12)<=E16,15+IF((YEAR(E16)-YEAR($C16))>20,10,INT((YEAR(E16)-YEAR($C16)-1)/2)),0)) -> 16 | G16: =IF(E16="",0,IF(E16>=EDATE(C16,12),IF(E16<EDATE(C16,24),IF(C16<SET!$J$20,0,MIN(DATEDIF(C16,E16,"m"),11)),0),IF(D16>C16,IF(E16<=EDATE(C16,12),MIN(DATEDIF(C16,D16+1,"m"),11),0),MIN(DATEDIF(C16,E16,"m"),11)))) -> 0 | H16: 0.5 | I16: =COUNTIF(P16:BW16,SET!$C$15)*SET!$C$16+COUNTIF(P16:BW16,SET!$D$15)*SET!$D$16+COUNTIF(P16:BW16,SET!E$15)*SET!$E$16+COUNTIF(P16:BW16,SET!$F$15)*SET!$F$16+COUNTIF(P16:BW16,SET!$G$15)*SET!$G$16+COUNTIF(P16:BW16,SET!$H$15)*SET!$H$16+COUNTIF(P16:BW16,SET!$I$15)*SET!$I$16+COUNTIF(P16:BW16,)*SET!$K$16+COUNTIF(P16:BW16,SET!$M$15)*SET!$M$16 -> 12.5 | J16: =F16+G16+H16-I16 -> 4 | K16: =IF(E16="","",IF(AND(D16>C16,EDATE(IF(EDATE(C16,12)<D16,C16,E16),12)>D16),"퇴직정산",IF((E16-C16)>=365,EDATE(E16,12),EDATE(C16,24)))) -> 45663 | L16: =IF(K16="퇴직정산",J16,IF((M$2-C16)<365,"미확정",IF(M16="유예","유예",J16-M16))) -> 4 | M16: =IF(C16=0,0,IF(K16="퇴직정산",0,IF(J16<=0,0,IF(EDATE(C16,3)>M$2,"유예",IF(SET!$J$3="없음",0,IF(SET!$J$3="전부",IF(E16>=DATE(YEAR(SET!$I$11),MONTH(SET!$J$11),DAY(SET!$L$11)),MAX(0,F16-IF(I16<(G16+H16),0,(I16-(G16+H16)))),0),IF(E16>=DATE(YEAR(SET!$I$11),MONTH(SET!$J$11),DAY(SET!$L$11)),MAX(0,MIN(F16,SET!$L$3)-IF(I16<(G16+H16),0,(I16-(G16+H16)))),0))))))) -> 0 | N16: =IF(D16=0,IF(M16>0,IF((E16-C16)>=365,EDATE(E16,6),EDATE(K16,-6)),""),"") | O16: =IF(D16=0,IF(M16>0,IF((E16-C16)>=365,EDATE(E16,10),EDATE(K16,-2)),""),"") | P16: 반차 | Q16: 연차 | R16: 연차 | S16: 연차 | T16: 연차 | U16: 반차 | V16: 반차 | W16: 연차 | X16: 연차 | Y16: 연차 | Z16: 연차 | AA16: 연차 | AB16: 연차 | AC16: 연차
P17: 45293 | Q17: 45294 | R17: 45295 | S17: 45341 | T17: 45364 | U17: 45450 | V17: 45496 | W17: 45497 | X17: 45504 | Y17: 45513 | Z17: 45520 | AA17: 45521 | AB17: 45561 | AC17: 45603
A18: 환자안전 관리팀장 | B18: 이윤임 | C18: 43108 | D18: 45665 | E18: =IF(DATEDIF(C18,M$2,"m")<1,"",IF(C18=0,"",IF(EDATE(C18,12)<IF($D18>0,$D18-1,M$2),EDATE(C18,DATEDIF(C18,IF($D18>0,$D18-1,M$2+1),"y")*12),EDATE(C18,DATEDIF(C18,IF($D18>0,$D18-1,M$2+1),"m"))))) -> 45299 | F18: =IF(E18="",0,IF(EDATE(C18,12)<=E18,15+IF((YEAR(E18)-YEAR($C18))>20,10,INT((YEAR(E18)-YEAR($C18)-1)/2)),0)) -> 17 | G18: =IF(E18="",0,IF(E18>=EDATE(C18,12),IF(E18<EDATE(C18,24),IF(C18<SET!$J$20,0,MIN(DATEDIF(C18,E18,"m"),11)),0),IF(D18>C18,IF(E18<=EDATE(C18,12),MIN(DATEDIF(C18,D18+1,"m"),11),0),MIN(DATEDIF(C18,E18,"m"),11)))) -> 0 | H18: 0 | I18: =COUNTIF(P18:BW18,SET!$C$15)*SET!$C$16+COUNTIF(P18:BW18,SET!$D$15)*SET!$D$16+COUNTIF(P18:BW18,SET!E$15)*SET!$E$16+COUNTIF(P18:BW18,SET!$F$15)*SET!$F$16+COUNTIF(P18:BW18,SET!$G$15)*SET!$G$16+COUNTIF(P18:BW18,SET!$H$15)*SET!$H$16+COUNTIF(P18:BW18,SET!$I$15)*SET!$I$16+COUNTIF(P18:BW18,)*SET!$K$16+COUNTIF(P18:BW18,SET!$M$15)*SET!$M$16 -> 16.5 | J18: =F18+G18+H18-I18 -> 0.5 | K18: =IF(E18="","",IF(AND(D18>C18,EDATE(IF(EDATE(C18,12)<D18,C18,E18),12)>D18),"퇴직정산",IF((E18-C18)>=365,EDATE(E18,12),EDATE(C18,24)))) -> 45665 | L18: =IF(K18="퇴직정산",J18,IF((M$2-C18)<365,"미확정",IF(M18="유예","유예",J18-M18))) -> 0.5 | M18: =IF(C18=0,0,IF(K18="퇴직정산",0,IF(J18<=0,0,IF(EDATE(C18,3)>M$2,"유예",IF(SET!$J$3="없음",0,IF(SET!$J$3="전부",IF(E18>=DATE(YEAR(SET!$I$11),MONTH(SET!$J$11),DAY(SET!$L$11)),MAX(0,F18-IF(I18<(G18+H18),0,(I18-(G18+H18)))),0),IF(E18>=DATE(YEAR(SET!$I$11),MONTH(SET!$J$11),DAY(SET!$L$11)),MAX(0,MIN(F18,SET!$L$3)-IF(I18<(G18+H18),0,(I18-(G18+H18)))),0))))))) -> 0 | N18: =IF(D18=0,IF(M18>0,IF((E18-C18)>=365,EDATE(E18,6),EDATE(K18,-6)),""),"") | O18: =IF(D18=0,IF(M18>0,IF((E18-C18)>=365,EDATE(E18,10),EDATE(K18,-2)),""),"") | P18: 반차 | Q18: 반차 | R18: 연차 | S18: 연차 | T18: 연차 | U18: 반차 | V18: 반차 | W18: 연차 | X18: 연차 | Y18: 반차 | Z18: 연차 | AA18: 반차 | AB18: 반차 | AC18: 연차 | AD18: 반차 | AE18: 연차 | AF18: 연차 | AG18: 반차 | AH18: 반차 | AI18: 연차 | AJ18: 연차 | AK18: 반차
P19: 45379 | Q19: 45380 | R19: 45399 | S19: 45400 | T19: 45411 | U19: 45429 | V19: 45434 | W19: 45442 | X19: 45455 | Y19: 45477 | Z19: 45478 | AA19: 45485 | AB19: 45496 | AC19: 45545 | AD19: 45547 | AE19: 45548 | AF19: 45567 | AG19: 45579 | AH19: 45582 | AI19: 45610 | AJ19: 45611 | AK19: 45623
A20: 물리치료 | B20: 김난아 | C20: 43108 | D20: 45665 | E20: =IF(DATEDIF(C20,M$2,"m")<1,"",IF(C20=0,"",IF(EDATE(C20,12)<IF($D20>0,$D20-1,M$2),EDATE(C20,DATEDIF(C20,IF($D20>0,$D20-1,M$2+1),"y")*12),EDATE(C20,DATEDIF(C20,IF($D20>0,$D20-1,M$2+1),"m"))))) -> 45299 | F20: =IF(E20="",0,IF(EDATE(C20,12)<=E20,15+IF((YEAR(E20)-YEAR($C20))>20,10,INT((YEAR(E20)-YEAR($C20)-1)/2)),0)) -> 17 | G20: =IF(E20="",0,IF(E20>=EDATE(C20,12),IF(E20<EDATE(C20,24),IF(C20<SET!$J$20,0,MIN(DATEDIF(C20,E20,"m"),11)),0),IF(D20>C20,IF(E20<=EDATE(C20,12),MIN(DATEDIF(C20,D20+1,"m"),11),0),MIN(DATEDIF(C20,E20,"m"),11)))) -> 0 | H20: 5.5 | I20: =COUNTIF(P20:BW20,SET!$C$15)*SET!$C$16+COUNTIF(P20:BW20,SET!$D$15)*SET!$D$16+COUNTIF(P20:BW20,SET!E$15)*SET!$E$16+COUNTIF(P20:BW20,SET!$F$15)*SET!$F$16+COUNTIF(P20:BW20,SET!$G$15)*SET!$G$16+COUNTIF(P20:BW20,SET!$H$15)*SET!$H$16+COUNTIF(P20:BW20,SET!$I$15)*SET!$I$16+COUNTIF(P20:BW20,)*SET!$K$16+COUNTIF(P20:BW20,SET!$M$15)*SET!$M$16 -> 22.5 | J20: =F20+G20+H20-I20 -> 0 | K20: =IF(E20="","",IF(AND(D20>C20,EDATE(IF(EDATE(C20,12)<D20,C20,E20),12)>D20),"퇴직정산",IF((E20-C20)>=365,EDATE(E20,12),EDATE(C20,24)))) -> 45665 | L20: =IF(K20="퇴직정산",J20,IF((M$2-C20)<365,"미확정",IF(M20="유예","유예",J20-M20))) -> 0 | M20: =IF(C20=0,0,IF(K20="퇴직정산",0,IF(J20<=0,0,IF(EDATE(C20,3)>M$2,"유예",IF(SET!$J$3="없음",0,IF(SET!$J$3="전부",IF(E20>=DATE(YEAR(SET!$I$11),MONTH(SET!$J$11),DAY(SET!$L$11)),MAX(0,F20-IF(I20<(G20+H20),0,(I20-(G20+H20)))),0),IF(E20>=DATE(YEAR(SET!$I$11),MONTH(SET!$J$11),DAY(SET!$L$11)),MAX(0,MIN(F20,SET!$L$3)-IF(I20<(G20+H20),0,(I20-(G20+H20)))),0))))))) -> 0 | N20: =IF(D20=0,IF(M20>0,IF((E20-C20)>=365,EDATE(E20,6),EDATE(K20,-6)),""),"") | O20: =IF(D20=0,IF(M20>0,IF((E20-C20)>=365,EDATE(E20,10),EDATE(K20,-2)),""),"") | P20: 연차 | Q20: 연차 | R20: 연차 | S20: 반차 | T20: 반차 | U20: 반차 | V20: 연차 | W20: 반차 | X20: 반차 | Y20: 반차 | Z20: 반차 | AA20: 반차 | AB20: 반차 | AC20: 반차 | AD20: 반차 | AE20: 반차 | AF20: 반차 | AG20: 반차 | AH20: 반차 | AI20: 반차 | AJ20: 반차 | AK20: 연차 | AL20: 연차 | AM20: 연차 | AN20: 연차 | AO20: 연차 | AP20: 연차 | AQ20: 연차 | AR20: 연차 | AS20: 연차 | AT20: 연차
P21: 45266 | Q21: 45273 | R21: 45282 | S21: 45288 | T21: 45293 | U21: 45295 | V21: 45296 | W21: 45323 | X21: 45336 | Y21: 45345 | Z21: 45351 | AA21: 45355 | AB21: 45356 | AC21: 45357 | AD21: 45358 | AE21: 45359 | AF21: 45362 | AG21: 45363 | AH21: 45364 | AI21: 45365 | AJ21: 45366 | AK21: 45369 | AL21: 45370 | AM21: 45371 | AN21: 45372 | AO21: 45373 | AP21: 45376 | AQ21: 45377 | AR21: 45378 | AS21: 45379 | AT21: 45380
